Workbook

Sheet Overall
A1: Rank | B1: Name | C1: Role | D1: Role (full) | E1: Area | F1: Score | H1: key | I1: lookup
A2: =IF(F2="","",COUNTIF($F$2:$F$1000,">"&F2)+1) -> 1 | B2: Porunga | C2: GK | D2: =IF(C2="","",IFERROR(INDEX(Summary!$B$2:$B$14,MATCH(C2,Summary!$A$2:$A$14,0)),"?")) -> Goalkeeper | E2: =IF(C2="","",IFERROR(INDEX(Summary!$C$2:$C$14,MATCH(C2,Summary!$A$2:$A$14,0)),"?")) -> Portieri | F2: 109 | H2: =IF(OR(B2="",F2=""),"",F2-ROW()/100000) -> 108.99998 | I2: =IF(H2="","",C2&"|"&(COUNTIFS($C$2:$C$1000,C2,$H$2:$H$1000,">"&H2)+1)) -> GK|1
A3: =IF(F3="","",COUNTIF($F$2:$F$1000,">"&F3)+1) -> 1 | B3: Gojo | C3: CMF | D3: =IF(C3="","",IFERROR(INDEX(Summary!$B$2:$B$14,MATCH(C3,Summary!$A$2:$A$14,0)),"?")) -> Central Midfielder | E3: =IF(C3="","",IFERROR(INDEX(Summary!$C$2:$C$14,MATCH(C3,Summary!$A$2:$A$14,0)),"?")) -> Centrocampo | F3: 109 | H3: =IF(OR(B3="",F3=""),"",F3-ROW()/100000) -> 108.99997 | I3: =IF(H3="","",C3&"|"&(COUNTIFS($C$2:$C$1000,C3,$H$2:$H$1000,">"&H3)+1)) -> CMF|1
A4: =IF(F4="","",COUNTIF($F$2:$F$1000,">"&F4)+1) -> 1 | B4: Uchiha itachi | C4: CMF | D4: =IF(C4="","",IFERROR(INDEX(Summary!$B$2:$B$14,MATCH(C4,Summary!$A$2:$A$14,0)),"?")) -> Central Midfielder | E4: =IF(C4="","",IFERROR(INDEX(Summary!$C$2:$C$14,MATCH(C4,Summary!$A$2:$A$14,0)),"?")) -> Centrocampo | F4: 109 | H4: =IF(OR(B4="",F4=""),"",F4-ROW()/100000) -> 108.99996 | I4: =IF(H4="","",C4&"|"&(COUNTIFS($C$2:$C$1000,C4,$H$2:$H$1000,">"&H4)+1)) -> CMF|2
A5: =IF(F5="","",COUNTIF($F$2:$F$1000,">"&F5)+1) -> 1 | B5: Jiren | C5: CMF | D5: =IF(C5="","",IFERROR(INDEX(Summary!$B$2:$B$14,MATCH(C5,Summary!$A$2:$A$14,0)),"?")) -> Central Midfielder | E5: =IF(C5="","",IFERROR(INDEX(Summary!$C$2:$C$14,MATCH(C5,Summary!$A$2:$A$14,0)),"?")) -> Centrocampo | F5: 109 | H5: =IF(OR(B5="",F5=""),"",F5-ROW()/100000) -> 108.99995 | I5: =IF(H5="","",C5&"|"&(COUNTIFS($C$2:$C$1000,C5,$H$2:$H$1000,">"&H5)+1)) -> CMF|3
A6: =IF(F6="","",COUNTIF($F$2:$F$1000,">"&F6)+1) -> 1 | B6: Super Totti | C6: LWF | D6: =IF(C6="","",IFERROR(INDEX(Summary!$B$2:$B$14,MATCH(C6,Summary!$A$2:$A$14,0)),"?")) -> Left Wing Forward | E6: =IF(C6="","",IFERROR(INDEX(Summary!$C$2:$C$14,MATCH(C6,Summary!$A$2:$A$14,0)),"?")) -> Attacco | F6: 109 | H6: =IF(OR(B6="",F6=""),"",F6-ROW()/100000) -> 108.99994 | I6: =IF(H6="","",C6&"|"&(COUNTIFS($C$2:$C$1000,C6,$H$2:$H$1000,">"&H6)+1)) -> LWF|1
A7: =IF(F7="","",COUNTIF($F$2:$F$1000,">"&F7)+1) -> 1 | B7: Super Totti og | C7: RWF | D7: =IF(C7="","",IFERROR(INDEX(Summary!$B$2:$B$14,MATCH(C7,Summary!$A$2:$A$14,0)),"?")) -> Right Wing Forward | E7: =IF(C7="","",IFERROR(INDEX(Summary!$C$2:$C$14,MATCH(C7,Summary!$A$2:$A$14,0)),"?")) -> Attacco | F7: 109 | H7: =IF(OR(B7="",F7=""),"",F7-ROW()/100000) -> 108.99993 | I7: =IF(H7="","",C7&"|"&(COUNTIFS($C$2:$C$1000,C7,$H$2:$H$1000,">"&H7)+1)) -> RWF|1
A8: =IF(F8="","",COUNTIF($F$2:$F$1000,">"&F8)+1) -> 1 | B8: Super Totti 2 | C8: SS | D8: =IF(C8="","",IFERROR(INDEX(Summary!$B$2:$B$14,MATCH(C8,Summary!$A$2:$A$14,0)),"?")) -> Second Striker | E8: =IF(C8="","",IFERROR(INDEX(Summary!$C$2:$C$14,MATCH(C8,Summary!$A$2:$A$14,0)),"?")) -> Attacco | F8: 109 | H8: =IF(OR(B8="",F8=""),"",F8-ROW()/100000) -> 108.99992 | I8: =IF(H8="","",C8&"|"&(COUNTIFS($C$2:$C$1000,C8,$H$2:$H$1000,">"&H8)+1)) -> SS|1
A9: =IF(F9="","",COUNTIF($F$2:$F$1000,">"&F9)+1) -> 1 | B9: Jesus | C9: CF | D9: =IF(C9="","",IFERROR(INDEX(Summary!$B$2:$B$14,MATCH(C9,Summary!$A$2:$A$14,0)),"?")) -> Center Forward | E9: =IF(C9="","",IFERROR(INDEX(Summary!$C$2:$C$14,MATCH(C9,Summary!$A$2:$A$14,0)),"?")) -> Attacco | F9: 109 | H9: =IF(OR(B9="",F9=""),"",F9-ROW()/100000) -> 108.99991 | I9: =IF(H9="","",C9&"|"&(COUNTIFS($C$2:$C$1000,C9,$H$2:$H$1000,">"&H9)+1)) -> CF|1
A10: =IF(F10="","",COUNTIF($F$2:$F$1000,">"&F10)+1) -> 9 | B10: Sasuke | C10: LB | D10: =IF(C10="","",IFERROR(INDEX(Summary!$B$2:$B$14,MATCH(C10,Summary!$A$2:$A$14,0)),"?")) -> Left Back | E10: =IF(C10="","",IFERROR(INDEX(Summary!$C$2:$C$14,MATCH(C10,Summary!$A$2:$A$14,0)),"?")) -> Difensori | F10: 108 | H10: =IF(OR(B10="",F10=""),"",F10-ROW()/100000) -> 107.9999 | I10: =IF(H10="","",C10&"|"&(COUNTIFS($C$2:$C$1000,C10,$H$2:$H$1000,">"&H10)+1)) -> LB|1
A11: =IF(F11="","",COUNTIF($F$2:$F$1000,">"&F11)+1) -> 9 | B11: Goku | C11: CF | D11: =IF(C11="","",IFERROR(INDEX(Summary!$B$2:$B$14,MATCH(C11,Summary!$A$2:$A$14,0)),"?")) -> Center Forward | E11: =IF(C11="","",IFERROR(INDEX(Summary!$C$2:$C$14,MATCH(C11,Summary!$A$2:$A$14,0)),"?")) -> Attacco | F11: 108 | H11: =IF(OR(B11="",F11=""),"",F11-ROW()/100000) -> 107.99989 | I11: =IF(H11="","",C11&"|"&(COUNTIFS($C$2:$C$1000,C11,$H$2:$H$1000,">"&H11)+1)) -> CF|2
A12: =IF(F12="","",COUNTIF($F$2:$F$1000,">"&F12)+1) -> 9 | B12: Vegeta | C12: CF | D12: =IF(C12="","",IFERROR(INDEX(Summary!$B$2:$B$14,MATCH(C12,Summary!$A$2:$A$14,0)),"?")) -> Center Forward | E12: =IF(C12="","",IFERROR(INDEX(Summary!$C$2:$C$14,MATCH(C12,Summary!$A$2:$A$14,0)),"?")) -> Attacco | F12: 108 | H12: =IF(OR(B12="",F12=""),"",F12-ROW()/100000) -> 107.99988 | I12: =IF(H12="","",C12&"|"&(COUNTIFS($C$2:$C$1000,C12,$H$2:$H$1000,">"&H12)+1)) -> CF|3
A13: =IF(F13="","",COUNTIF($F$2:$F$1000,">"&F13)+1) -> 12 | B13: Isaac netero | C13: CMF | D13: =IF(C13="","",IFERROR(INDEX(Summary!$B$2:$B$14,MATCH(C13,Summary!$A$2:$A$14,0)),"?")) -> Central Midfielder | E13: =IF(C13="","",IFERROR(INDEX(Summary!$C$2:$C$14,MATCH(C13,Summary!$A$2:$A$14,0)),"?")) -> Centrocampo | F13: 106 | H13: =IF(OR(B13="",F13=""),"",F13-ROW()/100000) -> 105.99987 | I13: =IF(H13="","",C13&"|"&(COUNTIFS($C$2:$C$1000,C13,$H$2:$H$1000,">"&H13)+1)) -> CMF|4
... A419: =IF(F419="","",COUNTIF($F$2:$F$1000,">"&F419)+1) -> 418 | B419: Donald Trump | C419: GK | D419: =IF(C419="","",IFERROR(INDEX(Summary!$B$2:$B$14,MATCH(C419,Summary!$A$2:$A$14,0)),"?")) -> Goalkeeper | E419: =IF(C419="","",IFERROR(INDEX(Summary!$C$2:$C$14,MATCH(C419,Summary!$A$2:$A$14,0)),"?")) -> Portieri | F419: 40 | H419: =IF(OR(B419="",F419=""),"",F419-ROW()/100000) -> 39.99581 | I419: =IF(H419="","",C419&"|"&(COUNTIFS($C$2:$C$1000,C419,$H$2:$H$1000,">"&H419)+1)) -> GK|36
A420: =IF(F420="","",COUNTIF($F$2:$F$1000,">"&F420)+1) | D420: =IF(C420="","",IFERROR(INDEX(Summary!$B$2:$B$14,MATCH(C420,Summary!$A$2:$A$14,0)),"?")) | E420: =IF(C420="","",IFERROR(INDEX(Summary!$C$2:$C$14,MATCH(C420,Summary!$A$2:$A$14,0)),"?")) | H420: =IF(OR(B420="",F420=""),"",F420-ROW()/100000) | I420: =IF(H420="","",C420&"|"&(COUNTIFS($C$2:$C$1000,C420,$H$2:$H$1000,">"&H420)+1))
A421: =IF(F421="","",COUNTIF($F$2:$F$1000,">"&F421)+1) | D421: =IF(C421="","",IFERROR(INDEX(Summary!$B$2:$B$14,MATCH(C421,Summary!$A$2:$A$14,0)),"?")) | E421: =IF(C421="","",IFERROR(INDEX(Summary!$C$2:$C$14,MATCH(C421,Summary!$A$2:$A$14,0)),"?")) | H421: =IF(OR(B421="",F421=""),"",F421-ROW()/100000) | I421: =IF(H421="","",C421&"|"&(COUNTIFS($C$2:$C$1000,C421,$H$2:$H$1000,">"&H421)+1))
A422: =IF(F422="","",COUNTIF($F$2:$F$1000,">"&F422)+1) | D422: =IF(C422="","",IFERROR(INDEX(Summary!$B$2:$B$14,MATCH(C422,Summary!$A$2:$A$14,0)),"?")) | E422: =IF(C422="","",IFERROR(INDEX(Summary!$C$2:$C$14,MATCH(C422,Summary!$A$2:$A$14,0)),"?")) | H422: =IF(OR(B422="",F422=""),"",F422-ROW()/100000) | I422: =IF(H422="","",C422&"|"&(COUNTIFS($C$2:$C$1000,C422,$H$2:$H$1000,">"&H422)+1))
A423: =IF(F423="","",COUNTIF($F$2:$F$1000,">"&F423)+1) | D423: =IF(C423="","",IFERROR(INDEX(Summary!$B$2:$B$14,MATCH(C423,Summary!$A$2:$A$14,0)),"?")) | E423: =IF(C423="","",IFERROR(INDEX(Summary!$C$2:$C$14,MATCH(C423,Summary!$A$2:$A$14,0)),"?")) | H423: =IF(OR(B423="",F423=""),"",F423-ROW()/100000) | I423: =IF(H423="","",C423&"|"&(COUNTIFS($C$2:$C$1000,C423,$H$2:$H$1000,">"&H423)+1))
A424: =IF(F424="","",COUNTIF($F$2:$F$1000,">"&F424)+1) | D424: =IF(C424="","",IFERROR(INDEX(Summary!$B$2:$B$14,MATCH(C424,Summary!$A$2:$A$14,0)),"?")) | E424: =IF(C424="","",IFERROR(INDEX(Summary!$C$2:$C$14,MATCH(C424,Summary!$A$2:$A$14,0)),"?")) | H424: =IF(OR(B424="",F424=""),"",F424-ROW()/100000) | I424: =IF(H424="","",C424&"|"&(COUNTIFS($C$2:$C$1000,C424,$H$2:$H$1000,">"&H424)+1))
A425: =IF(F425="","",COUNTIF($F$2:$F$1000,">"&F425)+1) | D425: =IF(C425="","",IFERROR(INDEX(Summary!$B$2:$B$14,MATCH(C425,Summary!$A$2:$A$14,0)),"?")) | E425: =IF(C425="","",IFERROR(INDEX(Summary!$C$2:$C$14,MATCH(C425,Summary!$A$2:$A$14,0)),"?")) | H425: =IF(OR(B425="",F425=""),"",F425-ROW()/100000) | I425: =IF(H425="","",C425&"|"&(COUNTIFS($C$2:$C$1000,C425,$H$2:$H$1000,">"&H425)+1))
A426: =IF(F426="","",COUNTIF($F$2:$F$1000,">"&F426)+1) | D426: =IF(C426="","",IFERROR(INDEX(Summary!$B$2:$B$14,MATCH(C426,Summary!$A$2:$A$14,0)),"?")) | E426: =IF(C426="","",IFERROR(INDEX(Summary!$C$2:$C$14,MATCH(C426,Summary!$A$2:$A$14,0)),"?")) | H426: =IF(OR(B426="",F426=""),"",F426-ROW()/100000) | I426: =IF(H426="","",C426&"|"&(COUNTIFS($C$2:$C$1000,C426,$H$2:$H$1000,">"&H426)+1))
A427: =IF(F427="","",COUNTIF($F$2:$F$1000,">"&F427)+1) | D427: =IF(C427="","",IFERROR(INDEX(Summary!$B$2:$B$14,MATCH(C427,Summary!$A$2:$A$14,0)),"?")) | E427: =IF(C427="","",IFERROR(INDEX(Summary!$C$2:$C$14,MATCH(C427,Summary!$A$2:$A$14,0)),"?")) | H427: =IF(OR(B427="",F427=""),"",F427-ROW()/100000) | I427: =IF(H427="","",C427&"|"&(COUNTIFS($C$2:$C$1000,C427,$H$2:$H$1000,">"&H427)+1))
A428: =IF(F428="","",COUNTIF($F$2:$F$1000,">"&F428)+1) | D428: =IF(C428="","",IFERROR(INDEX(Summary!$B$2:$B$14,MATCH(C428,Summary!$A$2:$A$14,0)),"?")) | E428: =IF(C428="","",IFERROR(INDEX(Summary!$C$2:$C$14,MATCH(C428,Summary!$A$2:$A$14,0)),"?")) | H428: =IF(OR(B428="",F428=""),"",F428-ROW()/100000) | I428: =IF(H428="","",C428&"|"&(COUNTIFS($C$2:$C$1000,C428,$H$2:$H$1000,">"&H428)+1))
A429: =IF(F429="","",COUNTIF($F$2:$F$1000,">"&F429)+1) | D429: =IF(C429="","",IFERROR(INDEX(Summary!$B$2:$B$14,MATCH(C429,Summary!$A$2:$A$14,0)),"?")) | E429: =IF(C429="","",IFERROR(INDEX(Summary!$C$2:$C$14,MATCH(C429,Summary!$A$2:$A$14,0)),"?")) | H429: =IF(OR(B429="",F429=""),"",F429-ROW()/100000) | I429: =IF(H429="","",C429&"|"&(COUNTIFS($C$2:$C$1000,C429,$H$2:$H$1000,">"&H429)+1))
A430: =IF(F430="","",COUNTIF($F$2:$F$1000,">"&F430)+1) | D430: =IF(C430="","",IFERROR(INDEX(Summary!$B$2:$B$14,MATCH(C430,Summary!$A$2:$A$14,0)),"?")) | E430: =IF(C430="","",IFERROR(INDEX(Summary!$C$2:$C$14,MATCH(C430,Summary!$A$2:$A$14,0)),"?")) | H430: =IF(OR(B430="",F430=""),"",F430-ROW()/100000) | I430: =IF(H430="","",C430&"|"&(COUNTIFS($C$2:$C$1000,C430,$H$2:$H$1000,">"&H430)+1))
A431: =IF(F431="","",COUNTIF($F$2:$F$1000,">"&F431)+1) | D431: =IF(C431="","",IFERROR(INDEX(Summary!$B$2:$B$14,MATCH(C431,Summary!$A$2:$A$14,0)),"?")) | E431: =IF(C431="","",IFERROR(INDEX(Summary!$C$2:$C$14,MATCH(C431,Summary!$A$2:$A$14,0)),"?")) | H431: =IF(OR(B431="",F431=""),"",F431-ROW()/100000) | I431: =IF(H431="","",C431&"|"&(COUNTIFS($C$2:$C$1000,C431,$H$2:$H$1000,">"&H431)+1))
... A1000: =IF(F1000="","",COUNTIF($F$2:$F$1000,">"&F1000)+1) | D1000: =IF(C1000="","",IFERROR(INDEX(Summary!$B$2:$B$14,MATCH(C1000,Summary!$A$2:$A$14,0)),"?")) | E1000: =IF(C1000="","",IFERROR(INDEX(Summary!$C$2:$C$14,MATCH(C1000,Summary!$A$2:$A$14,0)),"?")) | H1000: =IF(OR(B1000="",F1000=""),"",F1000-ROW()/100000) | I1000: =IF(H1000="","",C1000&"|"&(COUNTIFS($C$2:$C$1000,C1000,$H$2:$H$1000,">"&H1000)+1))

Sheet Summary
A1: Role | B1: Role (full) | C1: Area | D1: Players | E1: Top score | F1: Average | G1: Lowest
A2: GK | B2: Goalkeeper | C2: Portieri | D2: =COUNTIF(Overall!$C$2:$C$1000,A2) -> 36 | E2: =IF(D2=0,"",MAX(GK!$C$2:$C$151)) -> 109 | F2: =IF(D2=0,"",AVERAGE(GK!$C$2:$C$151)) -> 85.416667 | G2: =IF(D2=0,"",MIN(GK!$C$2:$C$151)) -> 40
A3: CB | B3: Center Back | C3: Difensori | D3: =COUNTIF(Overall!$C$2:$C$1000,A3) -> 73 | E3: =IF(D3=0,"",MAX(CB!$C$2:$C$151)) -> 100 | F3: =IF(D3=0,"",AVERAGE(CB!$C$2:$C$151)) -> 84.260274 | G3: =IF(D3=0,"",MIN(CB!$C$2:$C$151)) -> 76
A4: LB | B4: Left Back | C4: Difensori | D4: =COUNTIF(Overall!$C$2:$C$1000,A4) -> 22 | E4: =IF(D4=0,"",MAX(LB!$C$2:$C$151)) -> 108 | F4: =IF(D4=0,"",AVERAGE(LB!$C$2:$C$151)) -> 84.681818 | G4: =IF(D4=0,"",MIN(LB!$C$2:$C$151)) -> 76
A5: RB | B5: Right Back | C5: Difensori | D5: =COUNTIF(Overall!$C$2:$C$1000,A5) -> 32 | E5: =IF(D5=0,"",MAX(RB!$C$2:$C$151)) -> 96 | F5: =IF(D5=0,"",AVERAGE(RB!$C$2:$C$151)) -> 83.1875 | G5: =IF(D5=0,"",MIN(RB!$C$2:$C$151)) -> 73
A6: DMF | B6: Defensive Midfielder | C6: Centrocampo | D6: =COUNTIF(Overall!$C$2:$C$1000,A6) -> 38 | E6: =IF(D6=0,"",MAX(DMF!$C$2:$C$151)) -> 98 | F6: =IF(D6=0,"",AVERAGE(DMF!$C$2:$C$151)) -> 85.026316 | G6: =IF(D6=0,"",MIN(DMF!$C$2:$C$151)) -> 73
A7: CMF | B7: Central Midfielder | C7: Centrocampo | D7: =COUNTIF(Overall!$C$2:$C$1000,A7) -> 38 | E7: =IF(D7=0,"",MAX(CMF!$C$2:$C$151)) -> 109 | F7: =IF(D7=0,"",AVERAGE(CMF!$C$2:$C$151)) -> 85.657895 | G7: =IF(D7=0,"",MIN(CMF!$C$2:$C$151)) -> 72
A8: LMF | B8: Left Midfielder | C8: Centrocampo | D8: =COUNTIF(Overall!$C$2:$C$1000,A8) -> 28 | E8: =IF(D8=0,"",MAX(LMF!$C$2:$C$151)) -> 99 | F8: =IF(D8=0,"",AVERAGE(LMF!$C$2:$C$151)) -> 84.714286 | G8: =IF(D8=0,"",MIN(LMF!$C$2:$C$151)) -> 76
A9: RMF | B9: Right Midfielder | C9: Centrocampo | D9: =COUNTIF(Overall!$C$2:$C$1000,A9) -> 25 | E9: =IF(D9=0,"",MAX(RMF!$C$2:$C$151)) -> 106 | F9: =IF(D9=0,"",AVERAGE(RMF!$C$2:$C$151)) -> 85.92 | G9: =IF(D9=0,"",MIN(RMF!$C$2:$C$151)) -> 79
A10: AMF | B10: Attacking Midfielder | C10: Centrocampo | D10: =COUNTIF(Overall!$C$2:$C$1000,A10) -> 28 | E10: =IF(D10=0,"",MAX(AMF!$C$2:$C$151)) -> 103 | F10: =IF(D10=0,"",AVERAGE(AMF!$C$2:$C$151)) -> 86.285714 | G10: =IF(D10=0,"",MIN(AMF!$C$2:$C$151)) -> 77
A11: LWF | B11: Left Wing Forward | C11: Attacco | D11: =COUNTIF(Overall!$C$2:$C$1000,A11) -> 11 | E11: =IF(D11=0,"",MAX(LWF!$C$2:$C$151)) -> 109 | F11: =IF(D11=0,"",AVERAGE(LWF!$C$2:$C$151)) -> 88.363636 | G11: =IF(D11=0,"",MIN(LWF!$C$2:$C$151)) -> 77
A12: RWF | B12: Right Wing Forward | C12: Attacco | D12: =COUNTIF(Overall!$C$2:$C$1000,A12) -> 8 | E12: =IF(D12=0,"",MAX(RWF!$C$2:$C$151)) -> 109 | F12: =IF(D12=0,"",AVERAGE(RWF!$C$2:$C$151)) -> 85.375 | G12: =IF(D12=0,"",MIN(RWF!$C$2:$C$151)) -> 77
A13: SS | B13: Second Striker | C13: Attacco | D13: =COUNTIF(Overall!$C$2:$C$1000,A13) -> 18 | E13: =IF(D13=0,"",MAX(SS!$C$2:$C$151)) -> 109 | F13: =IF(D13=0,"",AVERAGE(SS!$C$2:$C$151)) -> 86.222222 | G13: =IF(D13=0,"",MIN(SS!$C$2:$C$151)) -> 74
A14: CF | B14: Center Forward | C14: Attacco | D14: =COUNTIF(Overall!$C$2:$C$1000,A14) -> 61 | E14: =IF(D14=0,"",MAX(CF!$C$2:$C$151)) -> 109 | F14: =IF(D14=0,"",AVERAGE(CF!$C$2:$C$151)) -> 88.901639 | G14: =IF(D14=0,"",MIN(CF!$C$2:$C$151)) -> 74
A15: Total | D15: =SUM(D2:D14) -> 418
A17: How it works
A18: Edit only the blue cells in Overall: Name, Role, Score. Rank, role name, area, every role tab and this summary update automatically.
A19: New players: add them in the first empty row of Overall (formulas are ready up to row 1000). Each role tab shows up to 150 players.
A20: Role must be one of the codes in column A of this sheet (Overall has a drop-down list).
A21: Overall keeps its row order when scores change: use the filter arrow on Score to re-sort it. Role tabs re-sort themselves.
A22: Ties: same rank number; order follows the row order in Overall.
A23: Source: Google Doc provided by the user. Duplicate names removed, keeping the first entry, except "Il cippe" (listed twice in RB).

Sheet GK
A1: Rank | B1: Name | C1: Score
A2: =IF(B2="","",COUNTIFS(Overall!$C$2:$C$1000,"GK",Overall!$F$2:$F$1000,">"&C2)+1) -> 1 | B2: =IFERROR(INDEX(Overall!$B$2:$B$1000,MATCH("GK|1",Overall!$I$2:$I$1000,0)),"") -> Porunga | C2: =IFERROR(INDEX(Overall!$F$2:$F$1000,MATCH("GK|1",Overall!$I$2:$I$1000,0)),"") -> 109
A3: =IF(B3="","",COUNTIFS(Overall!$C$2:$C$1000,"GK",Overall!$F$2:$F$1000,">"&C3)+1) -> 2 | B3: =IFERROR(INDEX(Overall!$B$2:$B$1000,MATCH("GK|2",Overall!$I$2:$I$1000,0)),"") -> Shenron | C3: =IFERROR(INDEX(Overall!$F$2:$F$1000,MATCH("GK|2",Overall!$I$2:$I$1000,0)),"") -> 104
A4: =IF(B4="","",COUNTIFS(Overall!$C$2:$C$1000,"GK",Overall!$F$2:$F$1000,">"&C4)+1) -> 3 | B4: =IFERROR(INDEX(Overall!$B$2:$B$1000,MATCH("GK|3",Overall!$I$2:$I$1000,0)),"") -> Broly | C4: =IFERROR(INDEX(Overall!$F$2:$F$1000,MATCH("GK|3",Overall!$I$2:$I$1000,0)),"") -> 101
A5: =IF(B5="","",COUNTIFS(Overall!$C$2:$C$1000,"GK",Overall!$F$2:$F$1000,">"&C5)+1) -> 4 | B5: =IFERROR(INDEX(Overall!$B$2:$B$1000,MATCH("GK|4",Overall!$I$2:$I$1000,0)),"") -> Hulk | C5: =IFERROR(INDEX(Overall!$F$2:$F$1000,MATCH("GK|4",Overall!$I$2:$I$1000,0)),"") -> 100
A6: =IF(B6="","",COUNTIFS(Overall!$C$2:$C$1000,"GK",Overall!$F$2:$F$1000,">"&C6)+1) -> 5 | B6: =IFERROR(INDEX(Overall!$B$2:$B$1000,MATCH("GK|5",Overall!$I$2:$I$1000,0)),"") -> Toppo | C6: =IFERROR(INDEX(Overall!$F$2:$F$1000,MATCH("GK|5",Overall!$I$2:$I$1000,0)),"") -> 98
A7: =IF(B7="","",COUNTIFS(Overall!$C$2:$C$1000,"GK",Overall!$F$2:$F$1000,">"&C7)+1) -> 6 | B7: =IFERROR(INDEX(Overall!$B$2:$B$1000,MATCH("GK|6",Overall!$I$2:$I$1000,0)),"") -> Dracula | C7: =IFERROR(INDEX(Overall!$F$2:$F$1000,MATCH("GK|6",Overall!$I$2:$I$1000,0)),"") -> 94
A8: =IF(B8="","",COUNTIFS(Overall!$C$2:$C$1000,"GK",Overall!$F$2:$F$1000,">"&C8)+1) -> 7 | B8: =IFERROR(INDEX(Overall!$B$2:$B$1000,MATCH("GK|7",Overall!$I$2:$I$1000,0)),"") -> Wakabayashi | C8: =IFERROR(INDEX(Overall!$F$2:$F$1000,MATCH("GK|7",Overall!$I$2:$I$1000,0)),"") -> 92
A9: =IF(B9="","",COUNTIFS(Overall!$C$2:$C$1000,"GK",Overall!$F$2:$F$1000,">"&C9)+1) -> 8 | B9: =IFERROR(INDEX(Overall!$B$2:$B$1000,MATCH("GK|8",Overall!$I$2:$I$1000,0)),"") -> Ectoplasm | C9: =IFERROR(INDEX(Overall!$F$2:$F$1000,MATCH("GK|8",Overall!$I$2:$I$1000,0)),"") -> 90
A10: =IF(B10="","",COUNTIFS(Overall!$C$2:$C$1000,"GK",Overall!$F$2:$F$1000,">"&C10)+1) -> 8 | B10: =IFERROR(INDEX(Overall!$B$2:$B$1000,MATCH("GK|9",Overall!$I$2:$I$1000,0)),"") -> Mark Evans | C10: =IFERROR(INDEX(Overall!$F$2:$F$1000,MATCH("GK|9",Overall!$I$2:$I$1000,0)),"") -> 90
A11: =IF(B11="","",COUNTIFS(Overall!$C$2:$C$1000,"GK",Overall!$F$2:$F$1000,">"&C11)+1) -> 8 | B11: =IFERROR(INDEX(Overall!$B$2:$B$1000,MATCH("GK|10",Overall!$I$2:$I$1000,0)),"") -> Andrea Discepolo | C11: =IFERROR(INDEX(Overall!$F$2:$F$1000,MATCH("GK|10",Overall!$I$2:$I$1000,0)),"") -> 90
A12: =IF(B12="","",COUNTIFS(Overall!$C$2:$C$1000,"GK",Overall!$F$2:$F$1000,">"&C12)+1) -> 11 | B12: =IFERROR(INDEX(Overall!$B$2:$B$1000,MATCH("GK|11",Overall!$I$2:$I$1000,0)),"") -> Shaq | C12: =IFERROR(INDEX(Overall!$F$2:$F$1000,MATCH("GK|11",Overall!$I$2:$I$1000,0)),"") -> 89
A13: =IF(B13="","",COUNTIFS(Overall!$C$2:$C$1000,"GK",Overall!$F$2:$F$1000,">"&C13)+1) -> 11 | B13: =IFERROR(INDEX(Overall!$B$2:$B$1000,MATCH("GK|12",Overall!$I$2:$I$1000,0)),"") -> Masella | C13: =IFERROR(INDEX(Overall!$F$2:$F$1000,MATCH("GK|12",Overall!$I$2:$I$1000,0)),"") -> 89
A14: =IF(B14="","",COUNTIFS(Overall!$C$2:$C$1000,"GK",Overall!$F$2:$F$1000,">"&C14)+1) -> 13 | B14: =IFERROR(INDEX(Overall!$B$2:$B$1000,MATCH("GK|13",Overall!$I$2:$I$1000,0)),"") -> Usopp | C14: =IFERROR(INDEX(Overall!$F$2:$F$1000,MATCH("GK|13",Overall!$I$2:$I$1000,0)),"") -> 88
A15: =IF(B15="","",COUNTIFS(Overall!$C$2:$C$1000,"GK",Overall!$F$2:$F$1000,">"&C15)+1) -> 14 | B15: =IFERROR(INDEX(Overall!$B$2:$B$1000,MATCH("GK|14",Overall!$I$2:$I$1000,0)),"") -> Jonathan Joestar | C15: =IFERROR(INDEX(Overall!$F$2:$F$1000,MATCH("GK|14",Overall!$I$2:$I$1000,0)),"") -> 86
A16: =IF(B16="","",COUNTIFS(Overall!$C$2:$C$1000,"GK",Overall!$F$2:$F$1000,">"&C16)+1) -> 14 | B16: =IFERROR(INDEX(Overall!$B$2:$B$1000,MATCH("GK|15",Overall!$I$2:$I$1000,0)),"") -> Maldonado | C16: =IFERROR(INDEX(Overall!$F$2:$F$1000,MATCH("GK|15",Overall!$I$2:$I$1000,0)),"") -> 86
A17: =IF(B17="","",COUNTIFS(Overall!$C$2:$C$1000,"GK",Overall!$F$2:$F$1000,">"&C17)+1) -> 16 | B17: =IFERROR(INDEX(Overall!$B$2:$B$1000,MATCH("GK|16",Overall!$I$2:$I$1000,0)),"") -> Pete | C17: =IFERROR(INDEX(Overall!$F$2:$F$1000,MATCH("GK|16",Overall!$I$2:$I$1000,0)),"") -> 85
A18: =IF(B18="","",COUNTIFS(Overall!$C$2:$C$1000,"GK",Overall!$F$2:$F$1000,">"&C18)+1) -> 16 | B18: =IFERROR(INDEX(Overall!$B$2:$B$1000,MATCH("GK|17",Overall!$I$2:$I$1000,0)),"") -> Franky | C18: =IFERROR(INDEX(Overall!$F$2:$F$1000,MATCH("GK|17",Overall!$I$2:$I$1000,0)),"") -> 85
A19: =IF(B19="","",COUNTIFS(Overall!$C$2:$C$1000,"GK",Overall!$F$2:$F$1000,">"&C19)+1) -> 16 | B19: =IFERROR(INDEX(Overall!$B$2:$B$1000,MATCH("GK|18",Overall!$I$2:$I$1000,0)),"") -> Spike Spiegel | C19: =IFERROR(INDEX(Overall!$F$2:$F$1000,MATCH("GK|18",Overall!$I$2:$I$1000,0)),"") -> 85
A20: =IF(B20="","",COUNTIFS(Overall!$C$2:$C$1000,"GK",Overall!$F$2:$F$1000,">"&C20)+1) -> 16 | B20: =IFERROR(INDEX(Overall!$B$2:$B$1000,MATCH("GK|19",Overall!$I$2:$I$1000,0)),"") -> C-3P0 | C20: =IFERROR(INDEX(Overall!$F$2:$F$1000,MATCH("GK|19",Overall!$I$2:$I$1000,0)),"") -> 85
A21: =IF(B21="","",COUNTIFS(Overall!$C$2:$C$1000,"GK",Overall!$F$2:$F$1000,">"&C21)+1) -> 16 | B21: =IFERROR(INDEX(Overall!$B$2:$B$1000,MATCH("GK|20",Overall!$I$2:$I$1000,0)),"") -> The Grinch | C21: =IFERROR(INDEX(Overall!$F$2:$F$1000,MATCH("GK|20",Overall!$I$2:$I$1000,0)),"") -> 85
A22: =IF(B22="","",COUNTIFS(Overall!$C$2:$C$1000,"GK",Overall!$F$2:$F$1000,">"&C22)+1) -> 21 | B22: =IFERROR(INDEX(Overall!$B$2:$B$1000,MATCH("GK|21",Overall!$I$2:$I$1000,0)),"") -> King Cold | C22: =IFERROR(INDEX(Overall!$F$2:$F$1000,MATCH("GK|21",Overall!$I$2:$I$1000,0)),"") -> 83
A23: =IF(B23="","",COUNTIFS(Overall!$C$2:$C$1000,"GK",Overall!$F$2:$F$1000,">"&C23)+1) -> 21 | B23: =IFERROR(INDEX(Overall!$B$2:$B$1000,MATCH("GK|22",Overall!$I$2:$I$1000,0)),"") -> Doomsday | C23: =IFERROR(INDEX(Overall!$F$2:$F$1000,MATCH("GK|22",Overall!$I$2:$I$1000,0)),"") -> 83
A24: =IF(B24="","",COUNTIFS(Overall!$C$2:$C$1000,"GK",Overall!$F$2:$F$1000,">"&C24)+1) -> 21 | B24: =IFERROR(INDEX(Overall!$B$2:$B$1000,MATCH("GK|23",Overall!$I$2:$I$1000,0)),"") -> Foghorn Leghorn | C24: =IFERROR(INDEX(Overall!$F$2:$F$1000,MATCH("GK|23",Overall!$I$2:$I$1000,0)),"") -> 83
A25: =IF(B25="","",COUNTIFS(Overall!$C$2:$C$1000,"GK",Overall!$F$2:$F$1000,">"&C25)+1) -> 24 | B25: =IFERROR(INDEX(Overall!$B$2:$B$1000,MATCH("GK|24",Overall!$I$2:$I$1000,0)),"") -> Bowser | C25: =IFERROR(INDEX(Overall!$F$2:$F$1000,MATCH("GK|24",Overall!$I$2:$I$1000,0)),"") -> 82
A26: =IF(B26="","",COUNTIFS(Overall!$C$2:$C$1000,"GK",Overall!$F$2:$F$1000,">"&C26)+1) -> 24 | B26: =IFERROR(INDEX(Overall!$B$2:$B$1000,MATCH("GK|25",Overall!$I$2:$I$1000,0)),"") -> Chief Wiggum | C26: =IFERROR(INDEX(Overall!$F$2:$F$1000,MATCH("GK|25",Overall!$I$2:$I$1000,0)),"") -> 82
A27: =IF(B27="","",COUNTIFS(Overall!$C$2:$C$1000,"GK",Overall!$F$2:$F$1000,">"&C27)+1) -> 24 | B27: =IFERROR(INDEX(Overall!$B$2:$B$1000,MATCH("GK|26",Overall!$I$2:$I$1000,0)),"") -> Mortis | C27: =IFERROR(INDEX(Overall!$F$2:$F$1000,MATCH("GK|26",Overall!$I$2:$I$1000,0)),"") -> 82
A28: =IF(B28="","",COUNTIFS(Overall!$C$2:$C$1000,"GK",Overall!$F$2:$F$1000,">"&C28)+1) -> 27 | B28: =IFERROR(INDEX(Overall!$B$2:$B$1000,MATCH("GK|27",Overall!$I$2:$I$1000,0)),"") -> Lord Slug | C28: =IFERROR(INDEX(Overall!$F$2:$F$1000,MATCH("GK|27",Overall!$I$2:$I$1000,0)),"") -> 81
A29: =IF(B29="","",COUNTIFS(Overall!$C$2:$C$1000,"GK",Overall!$F$2:$F$1000,">"&C29)+1) -> 27 | B29: =IFERROR(INDEX(Overall!$B$2:$B$1000,MATCH("GK|28",Overall!$I$2:$I$1000,0)),"") -> Parappa | C29: =IFERROR(INDEX(Overall!$F$2:$F$1000,MATCH("GK|28",Overall!$I$2:$I$1000,0)),"") -> 81
A30: =IF(B30="","",COUNTIFS(Overall!$C$2:$C$1000,"GK",Overall!$F$2:$F$1000,">"&C30)+1) -> 29 | B30: =IFERROR(INDEX(Overall!$B$2:$B$1000,MATCH("GK|29",Overall!$I$2:$I$1000,0)),"") -> King Dedede | C30: =IFERROR(INDEX(Overall!$F$2:$F$1000,MATCH("GK|29",Overall!$I$2:$I$1000,0)),"") -> 80
A31: =IF(B31="","",COUNTIFS(Overall!$C$2:$C$1000,"GK",Overall!$F$2:$F$1000,">"&C31)+1) -> 29 | B31: =IFERROR(INDEX(Overall!$B$2:$B$1000,MATCH("GK|30",Overall!$I$2:$I$1000,0)),"") -> Megazord | C31: =IFERROR(INDEX(Overall!$F$2:$F$1000,MATCH("GK|30",Overall!$I$2:$I$1000,0)),"") -> 80
A32: =IF(B32="","",COUNTIFS(Overall!$C$2:$C$1000,"GK",Overall!$F$2:$F$1000,">"&C32)+1) -> 29 | B32: =IFERROR(INDEX(Overall!$B$2:$B$1000,MATCH("GK|31",Overall!$I$2:$I$1000,0)),"") -> Harambe | C32: =IFERROR(INDEX(Overall!$F$2:$F$1000,MATCH("GK|31",Overall!$I$2:$I$1000,0)),"") -> 80
A33: =IF(B33="","",COUNTIFS(Overall!$C$2:$C$1000,"GK",Overall!$F$2:$F$1000,">"&C33)+1) -> 29 | B33: =IFERROR(INDEX(Overall!$B$2:$B$1000,MATCH("GK|32",Overall!$I$2:$I$1000,0)),"") -> Snorlax | C33: =IFERROR(INDEX(Overall!$F$2:$F$1000,MATCH("GK|32",Overall!$I$2:$I$1000,0)),"") -> 80
A34: =IF(B34="","",COUNTIFS(Overall!$C$2:$C$1000,"GK",Overall!$F$2:$F$1000,">"&C34)+1) -> 33 | B34: =IFERROR(INDEX(Overall!$B$2:$B$1000,MATCH("GK|33",Overall!$I$2:$I$1000,0)),"") -> Dr Nefario | C34: =IFERROR(INDEX(Overall!$F$2:$F$1000,MATCH("GK|33",Overall!$I$2:$I$1000,0)),"") -> 77
A35: =IF(B35="","",COUNTIFS(Overall!$C$2:$C$1000,"GK",Overall!$F$2:$F$1000,">"&C35)+1) -> 34 | B35: =IFERROR(INDEX(Overall!$B$2:$B$1000,MATCH("GK|34",Overall!$I$2:$I$1000,0)),"") -> Future | C35: =IFERROR(INDEX(Overall!$F$2:$F$1000,MATCH("GK|34",Overall!$I$2:$I$1000,0)),"") -> 76
A36: =IF(B36="","",COUNTIFS(Overall!$C$2:$C$1000,"GK",Overall!$F$2:$F$1000,">"&C36)+1) -> 35 | B36: =IFERROR(INDEX(Overall!$B$2:$B$1000,MATCH("GK|35",Overall!$I$2:$I$1000,0)),"") -> Martin Luther King | C36: =IFERROR(INDEX(Overall!$F$2:$F$1000,MATCH("GK|35",Overall!$I$2:$I$1000,0)),"") -> 74
A37: =IF(B37="","",COUNTIFS(Overall!$C$2:$C$1000,"GK",Overall!$F$2:$F$1000,">"&C37)+1) -> 36 | B37: =IFERROR(INDEX(Overall!$B$2:$B$1000,MATCH("GK|36",Overall!$I$2:$I$1000,0)),"") -> Donald Trump | C37: =IFERROR(INDEX(Overall!$F$2:$F$1000,MATCH("GK|36",Overall!$I$2:$I$1000,0)),"") -> 40
A38: =IF(B38="","",COUNTIFS(Overall!$C$2:$C$1000,"GK",Overall!$F$2:$F$1000,">"&C38)+1) | B38: =IFERROR(INDEX(Overall!$B$2:$B$1000,MATCH("GK|37",Overall!$I$2:$I$1000,0)),"") | C38: =IFERROR(INDEX(Overall!$F$2:$F$1000,MATCH("GK|37",Overall!$I$2:$I$1000,0)),"")
A39: =IF(B39="","",COUNTIFS(Overall!$C$2:$C$1000,"GK",Overall!$F$2:$F$1000,">"&C39)+1) | B39: =IFERROR(INDEX(Overall!$B$2:$B$1000,MATCH("GK|38",Overall!$I$2:$I$1000,0)),"") | C39: =IFERROR(INDEX(Overall!$F$2:$F$1000,MATCH("GK|38",Overall!$I$2:$I$1000,0)),"")
A40: =IF(B40="","",COUNTIFS(Overall!$C$2:$C$1000,"GK",Overall!$F$2:$F$1000,">"&C40)+1) | B40: =IFERROR(INDEX(Overall!$B$2:$B$1000,MATCH("GK|39",Overall!$I$2:$I$1000,0)),"") | C40: =IFERROR(INDEX(Overall!$F$2:$F$1000,MATCH("GK|39",Overall!$I$2:$I$1000,0)),"")
...

Sheet CB
A1: Rank | B1: Name | C1: Score
A2: =IF(B2="","",COUNTIFS(Overall!$C$2:$C$1000,"CB",Overall!$F$2:$F$1000,">"&C2)+1) -> 1 | B2: =IFERROR(INDEX(Overall!$B$2:$B$1000,MATCH("CB|1",Overall!$I$2:$I$1000,0)),"") -> Android 16 | C2: =IFERROR(INDEX(Overall!$F$2:$F$1000,MATCH("CB|1",Overall!$I$2:$I$1000,0)),"") -> 100
A3: =IF(B3="","",COUNTIFS(Overall!$C$2:$C$1000,"CB",Overall!$F$2:$F$1000,">"&C3)+1) -> 2 | B3: =IFERROR(INDEX(Overall!$B$2:$B$1000,MATCH("CB|2",Overall!$I$2:$I$1000,0)),"") -> Battle beast | C3: =IFERROR(INDEX(Overall!$F$2:$F$1000,MATCH("CB|2",Overall!$I$2:$I$1000,0)),"") -> 98
A4: =IF(B4="","",COUNTIFS(Overall!$C$2:$C$1000,"CB",Overall!$F$2:$F$1000,">"&C4)+1) -> 2 | B4: =IFERROR(INDEX(Overall!$B$2:$B$1000,MATCH("CB|3",Overall!$I$2:$I$1000,0)),"") -> Tom T Rosa | C4: =IFERROR(INDEX(Overall!$F$2:$F$1000,MATCH("CB|3",Overall!$I$2:$I$1000,0)),"") -> 98
A5: =IF(B5="","",COUNTIFS(Overall!$C$2:$C$1000,"CB",Overall!$F$2:$F$1000,">"&C5)+1) -> 4 | B5: =IFERROR(INDEX(Overall!$B$2:$B$1000,MATCH("CB|4",Overall!$I$2:$I$1000,0)),"") -> Papa monkey | C5: =IFERROR(INDEX(Overall!$F$2:$F$1000,MATCH("CB|4",Overall!$I$2:$I$1000,0)),"") -> 95
A6: =IF(B6="","",COUNTIFS(Overall!$C$2:$C$1000,"CB",Overall!$F$2:$F$1000,">"&C6)+1) -> 4 | B6: =IFERROR(INDEX(Overall!$B$2:$B$1000,MATCH("CB|5",Overall!$I$2:$I$1000,0)),"") -> Skips | C6: =IFERROR(INDEX(Overall!$F$2:$F$1000,MATCH("CB|5",Overall!$I$2:$I$1000,0)),"") -> 95
A7: =IF(B7="","",COUNTIFS(Overall!$C$2:$C$1000,"CB",Overall!$F$2:$F$1000,">"&C7)+1) -> 6 | B7: =IFERROR(INDEX(Overall!$B$2:$B$1000,MATCH("CB|6",Overall!$I$2:$I$1000,0)),"") -> Volpescu | C7: =IFERROR(INDEX(Overall!$F$2:$F$1000,MATCH("CB|6",Overall!$I$2:$I$1000,0)),"") -> 93
A8: =IF(B8="","",COUNTIFS(Overall!$C$2:$C$1000,"CB",Overall!$F$2:$F$1000,">"&C8)+1) -> 6 | B8: =IFERROR(INDEX(Overall!$B$2:$B$1000,MATCH("CB|7",Overall!$I$2:$I$1000,0)),"") -> Endeavor | C8: =IFERROR(INDEX(Overall!$F$2:$F$1000,MATCH("CB|7",Overall!$I$2:$I$1000,0)),"") -> 93
A9: =IF(B9="","",COUNTIFS(Overall!$C$2:$C$1000,"CB",Overall!$F$2:$F$1000,">"&C9)+1) -> 8 | B9: =IFERROR(INDEX(Overall!$B$2:$B$1000,MATCH("CB|8",Overall!$I$2:$I$1000,0)),"") -> Tommo | C9: =IFERROR(INDEX(Overall!$F$2:$F$1000,MATCH("CB|8",Overall!$I$2:$I$1000,0)),"") -> 92
A10: =IF(B10="","",COUNTIFS(Overall!$C$2:$C$1000,"CB",Overall!$F$2:$F$1000,">"&C10)+1) -> 9 | B10: =IFERROR(INDEX(Overall!$B$2:$B$1000,MATCH("CB|9",Overall!$I$2:$I$1000,0)),"") -> Bartholomew Kuma | C10: =IFERROR(INDEX(Overall!$F$2:$F$1000,MATCH("CB|9",Overall!$I$2:$I$1000,0)),"") -> 91
A11: =IF(B11="","",COUNTIFS(Overall!$C$2:$C$1000,"CB",Overall!$F$2:$F$1000,">"&C11)+1) -> 9 | B11: =IFERROR(INDEX(Overall!$B$2:$B$1000,MATCH("CB|10",Overall!$I$2:$I$1000,0)),"") -> Sullivan | C11: =IFERROR(INDEX(Overall!$F$2:$F$1000,MATCH("CB|10",Overall!$I$2:$I$1000,0)),"") -> 91
A12: =IF(B12="","",COUNTIFS(Overall!$C$2:$C$1000,"CB",Overall!$F$2:$F$1000,">"&C12)+1) -> 9 | B12: =IFERROR(INDEX(Overall!$B$2:$B$1000,MATCH("CB|11",Overall!$I$2:$I$1000,0)),"") -> Nico pertici | C12: =IFERROR(INDEX(Overall!$F$2:$F$1000,MATCH("CB|11",Overall!$I$2:$I$1000,0)),"") -> 91
A13: =IF(B13="","",COUNTIFS(Overall!$C$2:$C$1000,"CB",Overall!$F$2:$F$1000,">"&C13)+1) -> 9 | B13: =IFERROR(INDEX(Overall!$B$2:$B$1000,MATCH("CB|12",Overall!$I$2:$I$1000,0)),"") -> Zanghief | C13: =IFERROR(INDEX(Overall!$F$2:$F$1000,MATCH("CB|12",Overall!$I$2:$I$1000,0)),"") -> 91
A14: =IF(B14="","",COUNTIFS(Overall!$C$2:$C$1000,"CB",Overall!$F$2:$F$1000,">"&C14)+1) -> 13 | B14: =IFERROR(INDEX(Overall!$B$2:$B$1000,MATCH("CB|13",Overall!$I$2:$I$1000,0)),"") -> Nappa | C14: =IFERROR(INDEX(Overall!$F$2:$F$1000,MATCH("CB|13",Overall!$I$2:$I$1000,0)),"") -> 90
A15: =IF(B15="","",COUNTIFS(Overall!$C$2:$C$1000,"CB",Overall!$F$2:$F$1000,">"&C15)+1) -> 14 | B15: =IFERROR(INDEX(Overall!$B$2:$B$1000,MATCH("CB|14",Overall!$I$2:$I$1000,0)),"") -> Selkie | C15: =IFERROR(INDEX(Overall!$F$2:$F$1000,MATCH("CB|14",Overall!$I$2:$I$1000,0)),"") -> 89
A16: =IF(B16="","",COUNTIFS(Overall!$C$2:$C$1000,"CB",Overall!$F$2:$F$1000,">"&C16)+1) -> 15 | B16: =IFERROR(INDEX(Overall!$B$2:$B$1000,MATCH("CB|15",Overall!$I$2:$I$1000,0)),"") -> Chewbacca | C16: =IFERROR(INDEX(Overall!$F$2:$F$1000,MATCH("CB|15",Overall!$I$2:$I$1000,0)),"") -> 88
A17: =IF(B17="","",COUNTIFS(Overall!$C$2:$C$1000,"CB",Overall!$F$2:$F$1000,">"&C17)+1) -> 15 | B17: =IFERROR(INDEX(Overall!$B$2:$B$1000,MATCH("CB|16",Overall!$I$2:$I$1000,0)),"") -> Seto Kaiba | C17: =IFERROR(INDEX(Overall!$F$2:$F$1000,MATCH("CB|16",Overall!$I$2:$I$1000,0)),"") -> 88
A18: =IF(B18="","",COUNTIFS(Overall!$C$2:$C$1000,"CB",Overall!$F$2:$F$1000,">"&C18)+1) -> 17 | B18: =IFERROR(INDEX(Overall!$B$2:$B$1000,MATCH("CB|17",Overall!$I$2:$I$1000,0)),"") -> Diavolo | C18: =IFERROR(INDEX(Overall!$F$2:$F$1000,MATCH("CB|17",Overall!$I$2:$I$1000,0)),"") -> 87
A19: =IF(B19="","",COUNTIFS(Overall!$C$2:$C$1000,"CB",Overall!$F$2:$F$1000,">"&C19)+1) -> 18 | B19: =IFERROR(INDEX(Overall!$B$2:$B$1000,MATCH("CB|18",Overall!$I$2:$I$1000,0)),"") -> Jozu | C19: =IFERROR(INDEX(Overall!$F$2:$F$1000,MATCH("CB|18",Overall!$I$2:$I$1000,0)),"") -> 86
A20: =IF(B20="","",COUNTIFS(Overall!$C$2:$C$1000,"CB",Overall!$F$2:$F$1000,">"&C20)+1) -> 18 | B20: =IFERROR(INDEX(Overall!$B$2:$B$1000,MATCH("CB|19",Overall!$I$2:$I$1000,0)),"") -> Thor stoutberg | C20: =IFERROR(INDEX(Overall!$F$2:$F$1000,MATCH("CB|19",Overall!$I$2:$I$1000,0)),"") -> 86
A21: =IF(B21="","",COUNTIFS(Overall!$C$2:$C$1000,"CB",Overall!$F$2:$F$1000,">"&C21)+1) -> 18 | B21: =IFERROR(INDEX(Overall!$B$2:$B$1000,MATCH("CB|20",Overall!$I$2:$I$1000,0)),"") -> Bull | C21: =IFERROR(INDEX(Overall!$F$2:$F$1000,MATCH("CB|20",Overall!$I$2:$I$1000,0)),"") -> 86
A22: =IF(B22="","",COUNTIFS(Overall!$C$2:$C$1000,"CB",Overall!$F$2:$F$1000,">"&C22)+1) -> 18 | B22: =IFERROR(INDEX(Overall!$B$2:$B$1000,MATCH("CB|21",Overall!$I$2:$I$1000,0)),"") -> Eijiro | C22: =IFERROR(INDEX(Overall!$F$2:$F$1000,MATCH("CB|21",Overall!$I$2:$I$1000,0)),"") -> 86
A23: =IF(B23="","",COUNTIFS(Overall!$C$2:$C$1000,"CB",Overall!$F$2:$F$1000,">"&C23)+1) -> 18 | B23: =IFERROR(INDEX(Overall!$B$2:$B$1000,MATCH("CB|22",Overall!$I$2:$I$1000,0)),"") -> Shrek | C23: =IFERROR(INDEX(Overall!$F$2:$F$1000,MATCH("CB|22",Overall!$I$2:$I$1000,0)),"") -> 86
A24: =IF(B24="","",COUNTIFS(Overall!$C$2:$C$1000,"CB",Overall!$F$2:$F$1000,">"&C24)+1) -> 18 | B24: =IFERROR(INDEX(Overall!$B$2:$B$1000,MATCH("CB|23",Overall!$I$2:$I$1000,0)),"") -> Zamasu | C24: =IFERROR(INDEX(Overall!$F$2:$F$1000,MATCH("CB|23",Overall!$I$2:$I$1000,0)),"") -> 86
A25: =IF(B25="","",COUNTIFS(Overall!$C$2:$C$1000,"CB",Overall!$F$2:$F$1000,">"&C25)+1) -> 18 | B25: =IFERROR(INDEX(Overall!$B$2:$B$1000,MATCH("CB|24",Overall!$I$2:$I$1000,0)),"") -> Wario | C25: =IFERROR(INDEX(Overall!$F$2:$F$1000,MATCH("CB|24",Overall!$I$2:$I$1000,0)),"") -> 86
A26: =IF(B26="","",COUNTIFS(Overall!$C$2:$C$1000,"CB",Overall!$F$2:$F$1000,">"&C26)+1) -> 18 | B26: =IFERROR(INDEX(Overall!$B$2:$B$1000,MATCH("CB|25",Overall!$I$2:$I$1000,0)),"") -> Tien | C26: =IFERROR(INDEX(Overall!$F$2:$F$1000,MATCH("CB|25",Overall!$I$2:$I$1000,0)),"") -> 86
A27: =IF(B27="","",COUNTIFS(Overall!$C$2:$C$1000,"CB",Overall!$F$2:$F$1000,">"&C27)+1) -> 18 | B27: =IFERROR(INDEX(Overall!$B$2:$B$1000,MATCH("CB|26",Overall!$I$2:$I$1000,0)),"") -> Cyborg | C27: =IFERROR(INDEX(Overall!$F$2:$F$1000,MATCH("CB|26",Overall!$I$2:$I$1000,0)),"") -> 86
A28: =IF(B28="","",COUNTIFS(Overall!$C$2:$C$1000,"CB",Overall!$F$2:$F$1000,">"&C28)+1) -> 18 | B28: =IFERROR(INDEX(Overall!$B$2:$B$1000,MATCH("CB|27",Overall!$I$2:$I$1000,0)),"") -> Yusei Fudo | C28: =IFERROR(INDEX(Overall!$F$2:$F$1000,MATCH("CB|27",Overall!$I$2:$I$1000,0)),"") -> 86
A29: =IF(B29="","",COUNTIFS(Overall!$C$2:$C$1000,"CB",Overall!$F$2:$F$1000,">"&C29)+1) -> 28 | B29: =IFERROR(INDEX(Overall!$B$2:$B$1000,MATCH("CB|28",Overall!$I$2:$I$1000,0)),"") -> The immortal | C29: =IFERROR(INDEX(Overall!$F$2:$F$1000,MATCH("CB|28",Overall!$I$2:$I$1000,0)),"") -> 85
A30: =IF(B30="","",COUNTIFS(Overall!$C$2:$C$1000,"CB",Overall!$F$2:$F$1000,">"&C30)+1) -> 28 | B30: =IFERROR(INDEX(Overall!$B$2:$B$1000,MATCH("CB|29",Overall!$I$2:$I$1000,0)),"") -> Joseph joestar | C30: =IFERROR(INDEX(Overall!$F$2:$F$1000,MATCH("CB|29",Overall!$I$2:$I$1000,0)),"") -> 85
A31: =IF(B31="","",COUNTIFS(Overall!$C$2:$C$1000,"CB",Overall!$F$2:$F$1000,">"&C31)+1) -> 28 | B31: =IFERROR(INDEX(Overall!$B$2:$B$1000,MATCH("CB|30",Overall!$I$2:$I$1000,0)),"") -> Barbanera | C31: =IFERROR(INDEX(Overall!$F$2:$F$1000,MATCH("CB|30",Overall!$I$2:$I$1000,0)),"") -> 85
A32: =IF(B32="","",COUNTIFS(Overall!$C$2:$C$1000,"CB",Overall!$F$2:$F$1000,">"&C32)+1) -> 28 | B32: =IFERROR(INDEX(Overall!$B$2:$B$1000,MATCH("CB|31",Overall!$I$2:$I$1000,0)),"") -> T rex | C32: =IFERROR(INDEX(Overall!$F$2:$F$1000,MATCH("CB|31",Overall!$I$2:$I$1000,0)),"") -> 85
A33: =IF(B33="","",COUNTIFS(Overall!$C$2:$C$1000,"CB",Overall!$F$2:$F$1000,">"&C33)+1) -> 28 | B33: =IFERROR(INDEX(Overall!$B$2:$B$1000,MATCH("CB|32",Overall!$I$2:$I$1000,0)),"") -> Cookie monster | C33: =IFERROR(INDEX(Overall!$F$2:$F$1000,MATCH("CB|32",Overall!$I$2:$I$1000,0)),"") -> 85
A34: =IF(B34="","",COUNTIFS(Overall!$C$2:$C$1000,"CB",Overall!$F$2:$F$1000,">"&C34)+1) -> 28 | B34: =IFERROR(INDEX(Overall!$B$2:$B$1000,MATCH("CB|33",Overall!$I$2:$I$1000,0)),"") -> Caesar | C34: =IFERROR(INDEX(Overall!$F$2:$F$1000,MATCH("CB|33",Overall!$I$2:$I$1000,0)),"") -> 85
A35: =IF(B35="","",COUNTIFS(Overall!$C$2:$C$1000,"CB",Overall!$F$2:$F$1000,">"&C35)+1) -> 28 | B35: =IFERROR(INDEX(Overall!$B$2:$B$1000,MATCH("CB|34",Overall!$I$2:$I$1000,0)),"") -> Snoop dogg | C35: =IFERROR(INDEX(Overall!$F$2:$F$1000,MATCH("CB|34",Overall!$I$2:$I$1000,0)),"") -> 85
A36: =IF(B36="","",COUNTIFS(Overall!$C$2:$C$1000,"CB",Overall!$F$2:$F$1000,">"&C36)+1) -> 28 | B36: =IFERROR(INDEX(Overall!$B$2:$B$1000,MATCH("CB|35",Overall!$I$2:$I$1000,0)),"") -> Champa | C36: =IFERROR(INDEX(Overall!$F$2:$F$1000,MATCH("CB|35",Overall!$I$2:$I$1000,0)),"") -> 85
A37: =IF(B37="","",COUNTIFS(Overall!$C$2:$C$1000,"CB",Overall!$F$2:$F$1000,">"&C37)+1) -> 28 | B37: =IFERROR(INDEX(Overall!$B$2:$B$1000,MATCH("CB|36",Overall!$I$2:$I$1000,0)),"") -> Goofy | C37: =IFERROR(INDEX(Overall!$F$2:$F$1000,MATCH("CB|36",Overall!$I$2:$I$1000,0)),"") -> 85
A38: =IF(B38="","",COUNTIFS(Overall!$C$2:$C$1000,"CB",Overall!$F$2:$F$1000,">"&C38)+1) -> 28 | B38: =IFERROR(INDEX(Overall!$B$2:$B$1000,MATCH("CB|37",Overall!$I$2:$I$1000,0)),"") -> Venom | C38: =IFERROR(INDEX(Overall!$F$2:$F$1000,MATCH("CB|37",Overall!$I$2:$I$1000,0)),"") -> 85
A39: =IF(B39="","",COUNTIFS(Overall!$C$2:$C$1000,"CB",Overall!$F$2:$F$1000,">"&C39)+1) -> 38 | B39: =IFERROR(INDEX(Overall!$B$2:$B$1000,MATCH("CB|38",Overall!$I$2:$I$1000,0)),"") -> Juan | C39: =IFERROR(INDEX(Overall!$F$2:$F$1000,MATCH("CB|38",Overall!$I$2:$I$1000,0)),"") -> 84
A40: =IF(B40="","",COUNTIFS(Overall!$C$2:$C$1000,"CB",Overall!$F$2:$F$1000,">"&C40)+1) -> 39 | B40: =IFERROR(INDEX(Overall!$B$2:$B$1000,MATCH("CB|39",Overall!$I$2:$I$1000,0)),"") -> Rikido | C40: =IFERROR(INDEX(Overall!$F$2:$F$1000,MATCH("CB|39",Overall!$I$2:$I$1000,0)),"") -> 83
...

Sheet LB
A1: Rank | B1: Name | C1: Score
A2: =IF(B2="","",COUNTIFS(Overall!$C$2:$C$1000,"LB",Overall!$F$2:$F$1000,">"&C2)+1) -> 1 | B2: =IFERROR(INDEX(Overall!$B$2:$B$1000,MATCH("LB|1",Overall!$I$2:$I$1000,0)),"") -> Sasuke | C2: =IFERROR(INDEX(Overall!$F$2:$F$1000,MATCH("LB|1",Overall!$I$2:$I$1000,0)),"") -> 108
A3: =IF(B3="","",COUNTIFS(Overall!$C$2:$C$1000,"LB",Overall!$F$2:$F$1000,">"&C3)+1) -> 2 | B3: =IFERROR(INDEX(Overall!$B$2:$B$1000,MATCH("LB|2",Overall!$I$2:$I$1000,0)),"") -> Scimmia Monkey | C3: =IFERROR(INDEX(Overall!$F$2:$F$1000,MATCH("LB|2",Overall!$I$2:$I$1000,0)),"") -> 94
A4: =IF(B4="","",COUNTIFS(Overall!$C$2:$C$1000,"LB",Overall!$F$2:$F$1000,">"&C4)+1) -> 3 | B4: =IFERROR(INDEX(Overall!$B$2:$B$1000,MATCH("LB|3",Overall!$I$2:$I$1000,0)),"") -> Poly | C4: =IFERROR(INDEX(Overall!$F$2:$F$1000,MATCH("LB|3",Overall!$I$2:$I$1000,0)),"") -> 92
A5: =IF(B5="","",COUNTIFS(Overall!$C$2:$C$1000,"LB",Overall!$F$2:$F$1000,">"&C5)+1) -> 4 | B5: =IFERROR(INDEX(Overall!$B$2:$B$1000,MATCH("LB|4",Overall!$I$2:$I$1000,0)),"") -> Francesca Martella | C5: =IFERROR(INDEX(Overall!$F$2:$F$1000,MATCH("LB|4",Overall!$I$2:$I$1000,0)),"") -> 90
A6: =IF(B6="","",COUNTIFS(Overall!$C$2:$C$1000,"LB",Overall!$F$2:$F$1000,">"&C6)+1) -> 5 | B6: =IFERROR(INDEX(Overall!$B$2:$B$1000,MATCH("LB|5",Overall!$I$2:$I$1000,0)),"") -> Brook | C6: =IFERROR(INDEX(Overall!$F$2:$F$1000,MATCH("LB|5",Overall!$I$2:$I$1000,0)),"") -> 88
A7: =IF(B7="","",COUNTIFS(Overall!$C$2:$C$1000,"LB",Overall!$F$2:$F$1000,">"&C7)+1) -> 6 | B7: =IFERROR(INDEX(Overall!$B$2:$B$1000,MATCH("LB|6",Overall!$I$2:$I$1000,0)),"") -> Mike Wazowski | C7: =IFERROR(INDEX(Overall!$F$2:$F$1000,MATCH("LB|6",Overall!$I$2:$I$1000,0)),"") -> 87
A8: =IF(B8="","",COUNTIFS(Overall!$C$2:$C$1000,"LB",Overall!$F$2:$F$1000,">"&C8)+1) -> 7 | B8: =IFERROR(INDEX(Overall!$B$2:$B$1000,MATCH("LB|7",Overall!$I$2:$I$1000,0)),"") -> Sanji | C8: =IFERROR(INDEX(Overall!$F$2:$F$1000,MATCH("LB|7",Overall!$I$2:$I$1000,0)),"") -> 84
A9: =IF(B9="","",COUNTIFS(Overall!$C$2:$C$1000,"LB",Overall!$F$2:$F$1000,">"&C9)+1) -> 7 | B9: =IFERROR(INDEX(Overall!$B$2:$B$1000,MATCH("LB|8",Overall!$I$2:$I$1000,0)),"") -> Hurley Kane | C9: =IFERROR(INDEX(Overall!$F$2:$F$1000,MATCH("LB|8",Overall!$I$2:$I$1000,0)),"") -> 84
A10: =IF(B10="","",COUNTIFS(Overall!$C$2:$C$1000,"LB",Overall!$F$2:$F$1000,">"&C10)+1) -> 7 | B10: =IFERROR(INDEX(Overall!$B$2:$B$1000,MATCH("LB|9",Overall!$I$2:$I$1000,0)),"") -> Chance the rapper | C10: =IFERROR(INDEX(Overall!$F$2:$F$1000,MATCH("LB|9",Overall!$I$2:$I$1000,0)),"") -> 84
A11: =IF(B11="","",COUNTIFS(Overall!$C$2:$C$1000,"LB",Overall!$F$2:$F$1000,">"&C11)+1) -> 7 | B11: =IFERROR(INDEX(Overall!$B$2:$B$1000,MATCH("LB|10",Overall!$I$2:$I$1000,0)),"") -> Black panther | C11: =IFERROR(INDEX(Overall!$F$2:$F$1000,MATCH("LB|10",Overall!$I$2:$I$1000,0)),"") -> 84
A12: =IF(B12="","",COUNTIFS(Overall!$C$2:$C$1000,"LB",Overall!$F$2:$F$1000,">"&C12)+1) -> 11 | B12: =IFERROR(INDEX(Overall!$B$2:$B$1000,MATCH("LB|11",Overall!$I$2:$I$1000,0)),"") -> Waluigi | C12: =IFERROR(INDEX(Overall!$F$2:$F$1000,MATCH("LB|11",Overall!$I$2:$I$1000,0)),"") -> 83
A13: =IF(B13="","",COUNTIFS(Overall!$C$2:$C$1000,"LB",Overall!$F$2:$F$1000,">"&C13)+1) -> 11 | B13: =IFERROR(INDEX(Overall!$B$2:$B$1000,MATCH("LB|12",Overall!$I$2:$I$1000,0)),"") -> Jose Angel | C13: =IFERROR(INDEX(Overall!$F$2:$F$1000,MATCH("LB|12",Overall!$I$2:$I$1000,0)),"") -> 83
A14: =IF(B14="","",COUNTIFS(Overall!$C$2:$C$1000,"LB",Overall!$F$2:$F$1000,">"&C14)+1) -> 13 | B14: =IFERROR(INDEX(Overall!$B$2:$B$1000,MATCH("LB|13",Overall!$I$2:$I$1000,0)),"") -> Simba | C14: =IFERROR(INDEX(Overall!$F$2:$F$1000,MATCH("LB|13",Overall!$I$2:$I$1000,0)),"") -> 82
A15: =IF(B15="","",COUNTIFS(Overall!$C$2:$C$1000,"LB",Overall!$F$2:$F$1000,">"&C15)+1) -> 13 | B15: =IFERROR(INDEX(Overall!$B$2:$B$1000,MATCH("LB|14",Overall!$I$2:$I$1000,0)),"") -> Marge Simpson | C15: =IFERROR(INDEX(Overall!$F$2:$F$1000,MATCH("LB|14",Overall!$I$2:$I$1000,0)),"") -> 82
A16: =IF(B16="","",COUNTIFS(Overall!$C$2:$C$1000,"LB",Overall!$F$2:$F$1000,">"&C16)+1) -> 13 | B16: =IFERROR(INDEX(Overall!$B$2:$B$1000,MATCH("LB|15",Overall!$I$2:$I$1000,0)),"") -> Bert | C16: =IFERROR(INDEX(Overall!$F$2:$F$1000,MATCH("LB|15",Overall!$I$2:$I$1000,0)),"") -> 82
A17: =IF(B17="","",COUNTIFS(Overall!$C$2:$C$1000,"LB",Overall!$F$2:$F$1000,">"&C17)+1) -> 13 | B17: =IFERROR(INDEX(Overall!$B$2:$B$1000,MATCH("LB|16",Overall!$I$2:$I$1000,0)),"") -> Dynamike | C17: =IFERROR(INDEX(Overall!$F$2:$F$1000,MATCH("LB|16",Overall!$I$2:$I$1000,0)),"") -> 82
A18: =IF(B18="","",COUNTIFS(Overall!$C$2:$C$1000,"LB",Overall!$F$2:$F$1000,">"&C18)+1) -> 17 | B18: =IFERROR(INDEX(Overall!$B$2:$B$1000,MATCH("LB|17",Overall!$I$2:$I$1000,0)),"") -> Tweety | C18: =IFERROR(INDEX(Overall!$F$2:$F$1000,MATCH("LB|17",Overall!$I$2:$I$1000,0)),"") -> 81
A19: =IF(B19="","",COUNTIFS(Overall!$C$2:$C$1000,"LB",Overall!$F$2:$F$1000,">"&C19)+1) -> 17 | B19: =IFERROR(INDEX(Overall!$B$2:$B$1000,MATCH("LB|18",Overall!$I$2:$I$1000,0)),"") -> Greenway | C19: =IFERROR(INDEX(Overall!$F$2:$F$1000,MATCH("LB|18",Overall!$I$2:$I$1000,0)),"") -> 81
A20: =IF(B20="","",COUNTIFS(Overall!$C$2:$C$1000,"LB",Overall!$F$2:$F$1000,">"&C20)+1) -> 19 | B20: =IFERROR(INDEX(Overall!$B$2:$B$1000,MATCH("LB|19",Overall!$I$2:$I$1000,0)),"") -> Aquaman | C20: =IFERROR(INDEX(Overall!$F$2:$F$1000,MATCH("LB|19",Overall!$I$2:$I$1000,0)),"") -> 80
A21: =IF(B21="","",COUNTIFS(Overall!$C$2:$C$1000,"LB",Overall!$F$2:$F$1000,">"&C21)+1) -> 20 | B21: =IFERROR(INDEX(Overall!$B$2:$B$1000,MATCH("LB|20",Overall!$I$2:$I$1000,0)),"") -> Bo | C21: =IFERROR(INDEX(Overall!$F$2:$F$1000,MATCH("LB|20",Overall!$I$2:$I$1000,0)),"") -> 79
A22: =IF(B22="","",COUNTIFS(Overall!$C$2:$C$1000,"LB",Overall!$F$2:$F$1000,">"&C22)+1) -> 21 | B22: =IFERROR(INDEX(Overall!$B$2:$B$1000,MATCH("LB|21",Overall!$I$2:$I$1000,0)),"") -> Yamcha | C22: =IFERROR(INDEX(Overall!$F$2:$F$1000,MATCH("LB|21",Overall!$I$2:$I$1000,0)),"") -> 77
A23: =IF(B23="","",COUNTIFS(Overall!$C$2:$C$1000,"LB",Overall!$F$2:$F$1000,">"&C23)+1) -> 22 | B23: =IFERROR(INDEX(Overall!$B$2:$B$1000,MATCH("LB|22",Overall!$I$2:$I$1000,0)),"") -> Lanterna Verde | C23: =IFERROR(INDEX(Overall!$F$2:$F$1000,MATCH("LB|22",Overall!$I$2:$I$1000,0)),"") -> 76
A24: =IF(B24="","",COUNTIFS(Overall!$C$2:$C$1000,"LB",Overall!$F$2:$F$1000,">"&C24)+1) | B24: =IFERROR(INDEX(Overall!$B$2:$B$1000,MATCH("LB|23",Overall!$I$2:$I$1000,0)),"") | C24: =IFERROR(INDEX(Overall!$F$2:$F$1000,MATCH("LB|23",Overall!$I$2:$I$1000,0)),"")
A25: =IF(B25="","",COUNTIFS(Overall!$C$2:$C$1000,"LB",Overall!$F$2:$F$1000,">"&C25)+1) | B25: =IFERROR(INDEX(Overall!$B$2:$B$1000,MATCH("LB|24",Overall!$I$2:$I$1000,0)),"") | C25: =IFERROR(INDEX(Overall!$F$2:$F$1000,MATCH("LB|24",Overall!$I$2:$I$1000,0)),"")
A26: =IF(B26="","",COUNTIFS(Overall!$C$2:$C$1000,"LB",Overall!$F$2:$F$1000,">"&C26)+1) | B26: =IFERROR(INDEX(Overall!$B$2:$B$1000,MATCH("LB|25",Overall!$I$2:$I$1000,0)),"") | C26: =IFERROR(INDEX(Overall!$F$2:$F$1000,MATCH("LB|25",Overall!$I$2:$I$1000,0)),"")
A27: =IF(B27="","",COUNTIFS(Overall!$C$2:$C$1000,"LB",Overall!$F$2:$F$1000,">"&C27)+1) | B27: =IFERROR(INDEX(Overall!$B$2:$B$1000,MATCH("LB|26",Overall!$I$2:$I$1000,0)),"") | C27: =IFERROR(INDEX(Overall!$F$2:$F$1000,MATCH("LB|26",Overall!$I$2:$I$1000,0)),"")
A28: =IF(B28="","",COUNTIFS(Overall!$C$2:$C$1000,"LB",Overall!$F$2:$F$1000,">"&C28)+1) | B28: =IFERROR(INDEX(Overall!$B$2:$B$1000,MATCH("LB|27",Overall!$I$2:$I$1000,0)),"") | C28: =IFERROR(INDEX(Overall!$F$2:$F$1000,MATCH("LB|27",Overall!$I$2:$I$1000,0)),"")
A29: =IF(B29="","",COUNTIFS(Overall!$C$2:$C$1000,"LB",Overall!$F$2:$F$1000,">"&C29)+1) | B29: =IFERROR(INDEX(Overall!$B$2:$B$1000,MATCH("LB|28",Overall!$I$2:$I$1000,0)),"") | C29: =IFERROR(INDEX(Overall!$F$2:$F$1000,MATCH("LB|28",Overall!$I$2:$I$1000,0)),"")
A30: =IF(B30="","",COUNTIFS(Overall!$C$2:$C$1000,"LB",Overall!$F$2:$F$1000,">"&C30)+1) | B30: =IFERROR(INDEX(Overall!$B$2:$B$1000,MATCH("LB|29",Overall!$I$2:$I$1000,0)),"") | C30: =IFERROR(INDEX(Overall!$F$2:$F$1000,MATCH("LB|29",Overall!$I$2:$I$1000,0)),"")
A31: =IF(B31="","",COUNTIFS(Overall!$C$2:$C$1000,"LB",Overall!$F$2:$F$1000,">"&C31)+1) | B31: =IFERROR(INDEX(Overall!$B$2:$B$1000,MATCH("LB|30",Overall!$I$2:$I$1000,0)),"") | C31: =IFERROR(INDEX(Overall!$F$2:$F$1000,MATCH("LB|30",Overall!$I$2:$I$1000,0)),"")
A32: =IF(B32="","",COUNTIFS(Overall!$C$2:$C$1000,"LB",Overall!$F$2:$F$1000,">"&C32)+1) | B32: =IFERROR(INDEX(Overall!$B$2:$B$1000,MATCH("LB|31",Overall!$I$2:$I$1000,0)),"") | C32: =IFERROR(INDEX(Overall!$F$2:$F$1000,MATCH("LB|31",Overall!$I$2:$I$1000,0)),"")
A33: =IF(B33="","",COUNTIFS(Overall!$C$2:$C$1000,"LB",Overall!$F$2:$F$1000,">"&C33)+1) | B33: =IFERROR(INDEX(Overall!$B$2:$B$1000,MATCH("LB|32",Overall!$I$2:$I$1000,0)),"") | C33: =IFERROR(INDEX(Overall!$F$2:$F$1000,MATCH("LB|32",Overall!$I$2:$I$1000,0)),"")
A34: =IF(B34="","",COUNTIFS(Overall!$C$2:$C$1000,"LB",Overall!$F$2:$F$1000,">"&C34)+1) | B34: =IFERROR(INDEX(Overall!$B$2:$B$1000,MATCH("LB|33",Overall!$I$2:$I$1000,0)),"") | C34: =IFERROR(INDEX(Overall!$F$2:$F$1000,MATCH("LB|33",Overall!$I$2:$I$1000,0)),"")
A35: =IF(B35="","",COUNTIFS(Overall!$C$2:$C$1000,"LB",Overall!$F$2:$F$1000,">"&C35)+1) | B35: =IFERROR(INDEX(Overall!$B$2:$B$1000,MATCH("LB|34",Overall!$I$2:$I$1000,0)),"") | C35: =IFERROR(INDEX(Overall!$F$2:$F$1000,MATCH("LB|34",Overall!$I$2:$I$1000,0)),"")
A36: =IF(B36="","",COUNTIFS(Overall!$C$2:$C$1000,"LB",Overall!$F$2:$F$1000,">"&C36)+1) | B36: =IFERROR(INDEX(Overall!$B$2:$B$1000,MATCH("LB|35",Overall!$I$2:$I$1000,0)),"") | C36: =IFERROR(INDEX(Overall!$F$2:$F$1000,MATCH("LB|35",Overall!$I$2:$I$1000,0)),"")
A37: =IF(B37="","",COUNTIFS(Overall!$C$2:$C$1000,"LB",Overall!$F$2:$F$1000,">"&C37)+1) | B37: =IFERROR(INDEX(Overall!$B$2:$B$1000,MATCH("LB|36",Overall!$I$2:$I$1000,0)),"") | C37: =IFERROR(INDEX(Overall!$F$2:$F$1000,MATCH("LB|36",Overall!$I$2:$I$1000,0)),"")
A38: =IF(B38="","",COUNTIFS(Overall!$C$2:$C$1000,"LB",Overall!$F$2:$F$1000,">"&C38)+1) | B38: =IFERROR(INDEX(Overall!$B$2:$B$1000,MATCH("LB|37",Overall!$I$2:$I$1000,0)),"") | C38: =IFERROR(INDEX(Overall!$F$2:$F$1000,MATCH("LB|37",Overall!$I$2:$I$1000,0)),"")
A39: =IF(B39="","",COUNTIFS(Overall!$C$2:$C$1000,"LB",Overall!$F$2:$F$1000,">"&C39)+1) | B39: =IFERROR(INDEX(Overall!$B$2:$B$1000,MATCH("LB|38",Overall!$I$2:$I$1000,0)),"") | C39: =IFERROR(INDEX(Overall!$F$2:$F$1000,MATCH("LB|38",Overall!$I$2:$I$1000,0)),"")
A40: =IF(B40="","",COUNTIFS(Overall!$C$2:$C$1000,"LB",Overall!$F$2:$F$1000,">"&C40)+1) | B40: =IFERROR(INDEX(Overall!$B$2:$B$1000,MATCH("LB|39",Overall!$I$2:$I$1000,0)),"") | C40: =IFERROR(INDEX(Overall!$F$2:$F$1000,MATCH("LB|39",Overall!$I$2:$I$1000,0)),"")
...

Sheet RB
A1: Rank | B1: Name | C1: Score
A2: =IF(B2="","",COUNTIFS(Overall!$C$2:$C$1000,"RB",Overall!$F$2:$F$1000,">"&C2)+1) -> 1 | B2: =IFERROR(INDEX(Overall!$B$2:$B$1000,MATCH("RB|1",Overall!$I$2:$I$1000,0)),"") -> Il cippe | C2: =IFERROR(INDEX(Overall!$F$2:$F$1000,MATCH("RB|1",Overall!$I$2:$I$1000,0)),"") -> 96
A3: =IF(B3="","",COUNTIFS(Overall!$C$2:$C$1000,"RB",Overall!$F$2:$F$1000,">"&C3)+1) -> 1 | B3: =IFERROR(INDEX(Overall!$B$2:$B$1000,MATCH("RB|2",Overall!$I$2:$I$1000,0)),"") -> Il cippe | C3: =IFERROR(INDEX(Overall!$F$2:$F$1000,MATCH("RB|2",Overall!$I$2:$I$1000,0)),"") -> 96
A4: =IF(B4="","",COUNTIFS(Overall!$C$2:$C$1000,"RB",Overall!$F$2:$F$1000,">"&C4)+1) -> 3 | B4: =IFERROR(INDEX(Overall!$B$2:$B$1000,MATCH("RB|3",Overall!$I$2:$I$1000,0)),"") -> Gohan | C4: =IFERROR(INDEX(Overall!$F$2:$F$1000,MATCH("RB|3",Overall!$I$2:$I$1000,0)),"") -> 95
A5: =IF(B5="","",COUNTIFS(Overall!$C$2:$C$1000,"RB",Overall!$F$2:$F$1000,">"&C5)+1) -> 4 | B5: =IFERROR(INDEX(Overall!$B$2:$B$1000,MATCH("RB|4",Overall!$I$2:$I$1000,0)),"") -> Rotunno | C5: =IFERROR(INDEX(Overall!$F$2:$F$1000,MATCH("RB|4",Overall!$I$2:$I$1000,0)),"") -> 92
A6: =IF(B6="","",COUNTIFS(Overall!$C$2:$C$1000,"RB",Overall!$F$2:$F$1000,">"&C6)+1) -> 5 | B6: =IFERROR(INDEX(Overall!$B$2:$B$1000,MATCH("RB|5",Overall!$I$2:$I$1000,0)),"") -> Nami | C6: =IFERROR(INDEX(Overall!$F$2:$F$1000,MATCH("RB|5",Overall!$I$2:$I$1000,0)),"") -> 90
A7: =IF(B7="","",COUNTIFS(Overall!$C$2:$C$1000,"RB",Overall!$F$2:$F$1000,">"&C7)+1) -> 6 | B7: =IFERROR(INDEX(Overall!$B$2:$B$1000,MATCH("RB|6",Overall!$I$2:$I$1000,0)),"") -> Usain Bolt | C7: =IFERROR(INDEX(Overall!$F$2:$F$1000,MATCH("RB|6",Overall!$I$2:$I$1000,0)),"") -> 89
A8: =IF(B8="","",COUNTIFS(Overall!$C$2:$C$1000,"RB",Overall!$F$2:$F$1000,">"&C8)+1) -> 6 | B8: =IFERROR(INDEX(Overall!$B$2:$B$1000,MATCH("RB|7",Overall!$I$2:$I$1000,0)),"") -> Portgas D ace | C8: =IFERROR(INDEX(Overall!$F$2:$F$1000,MATCH("RB|7",Overall!$I$2:$I$1000,0)),"") -> 89
A9: =IF(B9="","",COUNTIFS(Overall!$C$2:$C$1000,"RB",Overall!$F$2:$F$1000,">"&C9)+1) -> 6 | B9: =IFERROR(INDEX(Overall!$B$2:$B$1000,MATCH("RB|8",Overall!$I$2:$I$1000,0)),"") -> Nanni | C9: =IFERROR(INDEX(Overall!$F$2:$F$1000,MATCH("RB|8",Overall!$I$2:$I$1000,0)),"") -> 89
A10: =IF(B10="","",COUNTIFS(Overall!$C$2:$C$1000,"RB",Overall!$F$2:$F$1000,">"&C10)+1) -> 9 | B10: =IFERROR(INDEX(Overall!$B$2:$B$1000,MATCH("RB|9",Overall!$I$2:$I$1000,0)),"") -> Ging freecss | C10: =IFERROR(INDEX(Overall!$F$2:$F$1000,MATCH("RB|9",Overall!$I$2:$I$1000,0)),"") -> 86
A11: =IF(B11="","",COUNTIFS(Overall!$C$2:$C$1000,"RB",Overall!$F$2:$F$1000,">"&C11)+1) -> 10 | B11: =IFERROR(INDEX(Overall!$B$2:$B$1000,MATCH("RB|10",Overall!$I$2:$I$1000,0)),"") -> Speedy Gonzales | C11: =IFERROR(INDEX(Overall!$F$2:$F$1000,MATCH("RB|10",Overall!$I$2:$I$1000,0)),"") -> 84
A12: =IF(B12="","",COUNTIFS(Overall!$C$2:$C$1000,"RB",Overall!$F$2:$F$1000,">"&C12)+1) -> 11 | B12: =IFERROR(INDEX(Overall!$B$2:$B$1000,MATCH("RB|11",Overall!$I$2:$I$1000,0)),"") -> Velociraptor | C12: =IFERROR(INDEX(Overall!$F$2:$F$1000,MATCH("RB|11",Overall!$I$2:$I$1000,0)),"") -> 83
A13: =IF(B13="","",COUNTIFS(Overall!$C$2:$C$1000,"RB",Overall!$F$2:$F$1000,">"&C13)+1) -> 11 | B13: =IFERROR(INDEX(Overall!$B$2:$B$1000,MATCH("RB|12",Overall!$I$2:$I$1000,0)),"") -> Heigoro | C13: =IFERROR(INDEX(Overall!$F$2:$F$1000,MATCH("RB|12",Overall!$I$2:$I$1000,0)),"") -> 83
A14: =IF(B14="","",COUNTIFS(Overall!$C$2:$C$1000,"RB",Overall!$F$2:$F$1000,">"&C14)+1) -> 11 | B14: =IFERROR(INDEX(Overall!$B$2:$B$1000,MATCH("RB|13",Overall!$I$2:$I$1000,0)),"") -> Crow | C14: =IFERROR(INDEX(Overall!$F$2:$F$1000,MATCH("RB|13",Overall!$I$2:$I$1000,0)),"") -> 83
A15: =IF(B15="","",COUNTIFS(Overall!$C$2:$C$1000,"RB",Overall!$F$2:$F$1000,">"&C15)+1) -> 14 | B15: =IFERROR(INDEX(Overall!$B$2:$B$1000,MATCH("RB|14",Overall!$I$2:$I$1000,0)),"") -> Green Arrow | C15: =IFERROR(INDEX(Overall!$F$2:$F$1000,MATCH("RB|14",Overall!$I$2:$I$1000,0)),"") -> 82
A16: =IF(B16="","",COUNTIFS(Overall!$C$2:$C$1000,"RB",Overall!$F$2:$F$1000,">"&C16)+1) -> 14 | B16: =IFERROR(INDEX(Overall!$B$2:$B$1000,MATCH("RB|15",Overall!$I$2:$I$1000,0)),"") -> Cassetti | C16: =IFERROR(INDEX(Overall!$F$2:$F$1000,MATCH("RB|15",Overall!$I$2:$I$1000,0)),"") -> 82
A17: =IF(B17="","",COUNTIFS(Overall!$C$2:$C$1000,"RB",Overall!$F$2:$F$1000,">"&C17)+1) -> 14 | B17: =IFERROR(INDEX(Overall!$B$2:$B$1000,MATCH("RB|16",Overall!$I$2:$I$1000,0)),"") -> Pb&J Time!! | C17: =IFERROR(INDEX(Overall!$F$2:$F$1000,MATCH("RB|16",Overall!$I$2:$I$1000,0)),"") -> 82
A18: =IF(B18="","",COUNTIFS(Overall!$C$2:$C$1000,"RB",Overall!$F$2:$F$1000,">"&C18)+1) -> 17 | B18: =IFERROR(INDEX(Overall!$B$2:$B$1000,MATCH("RB|17",Overall!$I$2:$I$1000,0)),"") -> Sideshow Bob | C18: =IFERROR(INDEX(Overall!$F$2:$F$1000,MATCH("RB|17",Overall!$I$2:$I$1000,0)),"") -> 81
A19: =IF(B19="","",COUNTIFS(Overall!$C$2:$C$1000,"RB",Overall!$F$2:$F$1000,">"&C19)+1) -> 17 | B19: =IFERROR(INDEX(Overall!$B$2:$B$1000,MATCH("RB|18",Overall!$I$2:$I$1000,0)),"") -> Raditz | C19: =IFERROR(INDEX(Overall!$F$2:$F$1000,MATCH("RB|18",Overall!$I$2:$I$1000,0)),"") -> 81
A20: =IF(B20="","",COUNTIFS(Overall!$C$2:$C$1000,"RB",Overall!$F$2:$F$1000,">"&C20)+1) -> 17 | B20: =IFERROR(INDEX(Overall!$B$2:$B$1000,MATCH("RB|19",Overall!$I$2:$I$1000,0)),"") -> Milhouse | C20: =IFERROR(INDEX(Overall!$F$2:$F$1000,MATCH("RB|19",Overall!$I$2:$I$1000,0)),"") -> 81
A21: =IF(B21="","",COUNTIFS(Overall!$C$2:$C$1000,"RB",Overall!$F$2:$F$1000,">"&C21)+1) -> 17 | B21: =IFERROR(INDEX(Overall!$B$2:$B$1000,MATCH("RB|20",Overall!$I$2:$I$1000,0)),"") -> Narancia | C21: =IFERROR(INDEX(Overall!$F$2:$F$1000,MATCH("RB|20",Overall!$I$2:$I$1000,0)),"") -> 81
A22: =IF(B22="","",COUNTIFS(Overall!$C$2:$C$1000,"RB",Overall!$F$2:$F$1000,">"&C22)+1) -> 17 | B22: =IFERROR(INDEX(Overall!$B$2:$B$1000,MATCH("RB|21",Overall!$I$2:$I$1000,0)),"") -> Gary | C22: =IFERROR(INDEX(Overall!$F$2:$F$1000,MATCH("RB|21",Overall!$I$2:$I$1000,0)),"") -> 81
A23: =IF(B23="","",COUNTIFS(Overall!$C$2:$C$1000,"RB",Overall!$F$2:$F$1000,">"&C23)+1) -> 22 | B23: =IFERROR(INDEX(Overall!$B$2:$B$1000,MATCH("RB|22",Overall!$I$2:$I$1000,0)),"") -> Brock | C23: =IFERROR(INDEX(Overall!$F$2:$F$1000,MATCH("RB|22",Overall!$I$2:$I$1000,0)),"") -> 80
A24: =IF(B24="","",COUNTIFS(Overall!$C$2:$C$1000,"RB",Overall!$F$2:$F$1000,">"&C24)+1) -> 22 | B24: =IFERROR(INDEX(Overall!$B$2:$B$1000,MATCH("RB|23",Overall!$I$2:$I$1000,0)),"") -> Ernie | C24: =IFERROR(INDEX(Overall!$F$2:$F$1000,MATCH("RB|23",Overall!$I$2:$I$1000,0)),"") -> 80
A25: =IF(B25="","",COUNTIFS(Overall!$C$2:$C$1000,"RB",Overall!$F$2:$F$1000,">"&C25)+1) -> 22 | B25: =IFERROR(INDEX(Overall!$B$2:$B$1000,MATCH("RB|24",Overall!$I$2:$I$1000,0)),"") -> Beast boy | C25: =IFERROR(INDEX(Overall!$F$2:$F$1000,MATCH("RB|24",Overall!$I$2:$I$1000,0)),"") -> 80
A26: =IF(B26="","",COUNTIFS(Overall!$C$2:$C$1000,"RB",Overall!$F$2:$F$1000,">"&C26)+1) -> 22 | B26: =IFERROR(INDEX(Overall!$B$2:$B$1000,MATCH("RB|25",Overall!$I$2:$I$1000,0)),"") -> Mortimer Mouse | C26: =IFERROR(INDEX(Overall!$F$2:$F$1000,MATCH("RB|25",Overall!$I$2:$I$1000,0)),"") -> 80
A27: =IF(B27="","",COUNTIFS(Overall!$C$2:$C$1000,"RB",Overall!$F$2:$F$1000,">"&C27)+1) -> 26 | B27: =IFERROR(INDEX(Overall!$B$2:$B$1000,MATCH("RB|26",Overall!$I$2:$I$1000,0)),"") -> Piper | C27: =IFERROR(INDEX(Overall!$F$2:$F$1000,MATCH("RB|26",Overall!$I$2:$I$1000,0)),"") -> 79
A28: =IF(B28="","",COUNTIFS(Overall!$C$2:$C$1000,"RB",Overall!$F$2:$F$1000,">"&C28)+1) -> 27 | B28: =IFERROR(INDEX(Overall!$B$2:$B$1000,MATCH("RB|27",Overall!$I$2:$I$1000,0)),"") -> Loki | C28: =IFERROR(INDEX(Overall!$F$2:$F$1000,MATCH("RB|27",Overall!$I$2:$I$1000,0)),"") -> 78
A29: =IF(B29="","",COUNTIFS(Overall!$C$2:$C$1000,"RB",Overall!$F$2:$F$1000,">"&C29)+1) -> 28 | B29: =IFERROR(INDEX(Overall!$B$2:$B$1000,MATCH("RB|28",Overall!$I$2:$I$1000,0)),"") -> Stewie griffin | C29: =IFERROR(INDEX(Overall!$F$2:$F$1000,MATCH("RB|28",Overall!$I$2:$I$1000,0)),"") -> 77
A30: =IF(B30="","",COUNTIFS(Overall!$C$2:$C$1000,"RB",Overall!$F$2:$F$1000,">"&C30)+1) -> 28 | B30: =IFERROR(INDEX(Overall!$B$2:$B$1000,MATCH("RB|29",Overall!$I$2:$I$1000,0)),"") -> Remy | C30: =IFERROR(INDEX(Overall!$F$2:$F$1000,MATCH("RB|29",Overall!$I$2:$I$1000,0)),"") -> 77
A31: =IF(B31="","",COUNTIFS(Overall!$C$2:$C$1000,"RB",Overall!$F$2:$F$1000,">"&C31)+1) -> 28 | B31: =IFERROR(INDEX(Overall!$B$2:$B$1000,MATCH("RB|30",Overall!$I$2:$I$1000,0)),"") -> Kamek | C31: =IFERROR(INDEX(Overall!$F$2:$F$1000,MATCH("RB|30",Overall!$I$2:$I$1000,0)),"") -> 77
A32: =IF(B32="","",COUNTIFS(Overall!$C$2:$C$1000,"RB",Overall!$F$2:$F$1000,">"&C32)+1) -> 31 | B32: =IFERROR(INDEX(Overall!$B$2:$B$1000,MATCH("RB|31",Overall!$I$2:$I$1000,0)),"") -> Koichi Hirose | C32: =IFERROR(INDEX(Overall!$F$2:$F$1000,MATCH("RB|31",Overall!$I$2:$I$1000,0)),"") -> 75
A33: =IF(B33="","",COUNTIFS(Overall!$C$2:$C$1000,"RB",Overall!$F$2:$F$1000,">"&C33)+1) -> 32 | B33: =IFERROR(INDEX(Overall!$B$2:$B$1000,MATCH("RB|32",Overall!$I$2:$I$1000,0)),"") -> Travis Scott | C33: =IFERROR(INDEX(Overall!$F$2:$F$1000,MATCH("RB|32",Overall!$I$2:$I$1000,0)),"") -> 73
A34: =IF(B34="","",COUNTIFS(Overall!$C$2:$C$1000,"RB",Overall!$F$2:$F$1000,">"&C34)+1) | B34: =IFERROR(INDEX(Overall!$B$2:$B$1000,MATCH("RB|33",Overall!$I$2:$I$1000,0)),"") | C34: =IFERROR(INDEX(Overall!$F$2:$F$1000,MATCH("RB|33",Overall!$I$2:$I$1000,0)),"")
A35: =IF(B35="","",COUNTIFS(Overall!$C$2:$C$1000,"RB",Overall!$F$2:$F$1000,">"&C35)+1) | B35: =IFERROR(INDEX(Overall!$B$2:$B$1000,MATCH("RB|34",Overall!$I$2:$I$1000,0)),"") | C35: =IFERROR(INDEX(Overall!$F$2:$F$1000,MATCH("RB|34",Overall!$I$2:$I$1000,0)),"")
A36: =IF(B36="","",COUNTIFS(Overall!$C$2:$C$1000,"RB",Overall!$F$2:$F$1000,">"&C36)+1) | B36: =IFERROR(INDEX(Overall!$B$2:$B$1000,MATCH("RB|35",Overall!$I$2:$I$1000,0)),"") | C36: =IFERROR(INDEX(Overall!$F$2:$F$1000,MATCH("RB|35",Overall!$I$2:$I$1000,0)),"")
A37: =IF(B37="","",COUNTIFS(Overall!$C$2:$C$1000,"RB",Overall!$F$2:$F$1000,">"&C37)+1) | B37: =IFERROR(INDEX(Overall!$B$2:$B$1000,MATCH("RB|36",Overall!$I$2:$I$1000,0)),"") | C37: =IFERROR(INDEX(Overall!$F$2:$F$1000,MATCH("RB|36",Overall!$I$2:$I$1000,0)),"")
A38: =IF(B38="","",COUNTIFS(Overall!$C$2:$C$1000,"RB",Overall!$F$2:$F$1000,">"&C38)+1) | B38: =IFERROR(INDEX(Overall!$B$2:$B$1000,MATCH("RB|37",Overall!$I$2:$I$1000,0)),"") | C38: =IFERROR(INDEX(Overall!$F$2:$F$1000,MATCH("RB|37",Overall!$I$2:$I$1000,0)),"")
A39: =IF(B39="","",COUNTIFS(Overall!$C$2:$C$1000,"RB",Overall!$F$2:$F$1000,">"&C39)+1) | B39: =IFERROR(INDEX(Overall!$B$2:$B$1000,MATCH("RB|38",Overall!$I$2:$I$1000,0)),"") | C39: =IFERROR(INDEX(Overall!$F$2:$F$1000,MATCH("RB|38",Overall!$I$2:$I$1000,0)),"")
A40: =IF(B40="","",COUNTIFS(Overall!$C$2:$C$1000,"RB",Overall!$F$2:$F$1000,">"&C40)+1) | B40: =IFERROR(INDEX(Overall!$B$2:$B$1000,MATCH("RB|39",Overall!$I$2:$I$1000,0)),"") | C40: =IFERROR(INDEX(Overall!$F$2:$F$1000,MATCH("RB|39",Overall!$I$2:$I$1000,0)),"")
...

Sheet DMF
A1: Rank | B1: Name | C1: Score
A2: =IF(B2="","",COUNTIFS(Overall!$C$2:$C$1000,"DMF",Overall!$F$2:$F$1000,">"&C2)+1) -> 1 | B2: =IFERROR(INDEX(Overall!$B$2:$B$1000,MATCH("DMF|1",Overall!$I$2:$I$1000,0)),"") -> Pietro frisoni | C2: =IFERROR(INDEX(Overall!$F$2:$F$1000,MATCH("DMF|1",Overall!$I$2:$I$1000,0)),"") -> 98
A3: =IF(B3="","",COUNTIFS(Overall!$C$2:$C$1000,"DMF",Overall!$F$2:$F$1000,">"&C3)+1) -> 2 | B3: =IFERROR(INDEX(Overall!$B$2:$B$1000,MATCH("DMF|2",Overall!$I$2:$I$1000,0)),"") -> Piccolo | C3: =IFERROR(INDEX(Overall!$F$2:$F$1000,MATCH("DMF|2",Overall!$I$2:$I$1000,0)),"") -> 96
A4: =IF(B4="","",COUNTIFS(Overall!$C$2:$C$1000,"DMF",Overall!$F$2:$F$1000,">"&C4)+1) -> 3 | B4: =IFERROR(INDEX(Overall!$B$2:$B$1000,MATCH("DMF|3",Overall!$I$2:$I$1000,0)),"") -> Cell | C4: =IFERROR(INDEX(Overall!$F$2:$F$1000,MATCH("DMF|3",Overall!$I$2:$I$1000,0)),"") -> 95
A5: =IF(B5="","",COUNTIFS(Overall!$C$2:$C$1000,"DMF",Overall!$F$2:$F$1000,">"&C5)+1) -> 4 | B5: =IFERROR(INDEX(Overall!$B$2:$B$1000,MATCH("DMF|4",Overall!$I$2:$I$1000,0)),"") -> Qarrad Monkey | C5: =IFERROR(INDEX(Overall!$F$2:$F$1000,MATCH("DMF|4",Overall!$I$2:$I$1000,0)),"") -> 94
